Workbook

Sheet 假设测算
A2: capex | B2: 资本性支出 | C2: =Capex清单!D15 -> 336.0032 | D2: 万元
A3: opex | B3: 费用 | C3: =Opex清单!D14 -> 15.703206 | D3: 万元
B4: 收入
C5: ①车位服务费 | E5: 每个车位XX天*充电量*度电单价
C6: 1 | D6: 天
C7: 1 | D7: 车位数
C8: 200 | D8: 车主充电(kwh)
C9: 0.4 | D9: kwh/元
C10: ③表后：客户价差收费 | F10: ③表后+④表前总收益等于储能峰谷套利收益
D11: 天 | E11: 比例
D12: 车位数
D13: 放电电量(kwh)
D14: kwh/元
C15: ④表前：峰谷价差
C16: 比例
C20: 辅助市场服务 | E20: 每年20次，每次1元/度，每次多少度待考证
C21: 相应次数
C25: ②政府补贴 | E25: 补贴有多少给客户
C26: 1 | D26: 天 | I26: 江苏政策：两部制到单一制
C27: 1 | D27: 车位数 | I27: 上海政策：相应次数
C28: 40 | D28: 放电电量(kwh)
C29: 0.8 | D29: kwh/元
C32: 第0年 | D32: 第1年 | E32: 第2年 | F32: 第3年 | G32: 第4年 | H32: 第5年 | I32: 第6年 | J32: 第7年 | K32: 第8年
B33: 收入
B34: ①车位服务费 | D34: =$C$6*$C$7*$C$8*$C$9/10000 -> 0.008 | E34: =$C$6*$C$7*$C$8*$C$9/10000 -> 0.008 | F34: =$C$6*$C$7*$C$8*$C$9/10000 -> 0.008 | G34: =$C$6*$C$7*$C$8*$C$9/10000 -> 0.008 | H34: =$C$6*$C$7*$C$8*$C$9/10000 -> 0.008 | I34: =$C$6*$C$7*$C$8*$C$9/10000 -> 0.008 | J34: =$C$6*$C$7*$C$8*$C$9/10000 -> 0.008 | K34: =$C$6*$C$7*$C$8*$C$9/10000 -> 0.008
B35: ②充放价差
B36: ③政府补贴
B40: 成本
B41: 税前利润
B42: 所得税 | C42: 三免三减半
B44: 净利润
B47: 现金流入
B48: 车位服务费
B49: 政府补偿
B50: 价差收益
B53: 现金流出
B54: 建设费用
B55: 运维费用
B56: 增值税
B57: 所得税
...

Sheet 输入
A1: =C4&"项目基础信息" -> 储充项目基础信息
A2: 工程及运营信息 | D2: 备注： | G2: 静态投资输入表(含税）
A3: 项目所在省份 | C3: 包头 | D3: 可做下拉框 | G3: 充电桩 | H3: 内容明细 | J3: 税率 | K3: 单价 | L3: 数量（套） | M3: 总价（万元） | N3: 增值税（万元） | O3: 原值（万元）
A4: 项目类型 | C4: 储充 | G4: 超充桩* | H4: 480kW一拖四 | J4: 0.13 | K4: 50 | L4: 1 | M4: =L4*K4 -> 50 | N4: =M4/(1+J4)*J4 -> 5.7522124 | O4: =M4-N4 -> 44.247788
A5: 项目开工年月日 | C5: 46265 | D5: 预估 | G5: 超充桩* | H5: 240kW一拖四 | J5: 0.13 | L5: 0 | M5: =L5*K5 -> 0 | N5: =M5/(1+J5)*J5 -> 0 | O5: =M5-N5 -> 0
A6: 建设期月数（估） | C6: 4 | D6: 预估 | G6: 直流桩* | H6: 120kW一拖二 | J6: 0.13 | K6: 3.5 | L6: 11 | M6: =L6*K6 -> 38.5 | N6: =M6/(1+J6)*J6 -> 4.4292035 | O6: =M6-N6 -> 34.070796
A7: 运营开始年月日 | C7: 46388 | D7: 预估 | G7: V2G桩* | H7: 132kW一拖二 | J7: 0.13 | K7: 9.8 | L7: 2 | M7: =L7*K7 -> 19.6 | N7: =M7/(1+J7)*J7 -> 2.2548673 | O7: =M7-N7 -> 17.345133
A8: 项目运营结束年月日 | G8: 施工安装 | H8: 电缆、土建、安装等 | J8: 0.09 | K8: 126.72 | L8: 1 | M8: =L8*K8 -> 126.72 | N8: =M8/(1+J8)*J8 -> 10.463119 | O8: =M8-N8 -> 116.25688
A9: 运行年限（年） | C9: =C17 -> 8 | D9: 年限不确定，初版按照充电桩寿命确定的运行年限 | G9: 储能系统
A10: 车位/充电桩配置 | G10: 储能柜* | H10: 262kWh工商储柜*1 | J10: 0.13 | K10: 18.3 | L10: 2 | M10: =L10*K10 -> 36.6 | N10: =M10/(1+J10)*J10 -> 4.2106195 | O10: =M10-N10 -> 32.389381
A11: 车位数-超充（个） | C11: 4 | G11: 施工安装 | H11: 安装+土建 | J11: 0.09 | K11: 23.58 | L11: 1 | M11: 23.58 | N11: =M11/(1+J11)*J11 -> 1.9469725 | O11: =M11-N11 -> 21.633028
A12: 车位数-快充（个） | C12: 22 | G12: 其它
A13: 车位数-慢充（个） | F13: 增加广告建设费用 | G13: 微网控制器EGC* | H13: 设备及授权 | J13: 0.13 | K13: 67.9 | L13: 1 | M13: 12.9 | N13: =M13/(1+J13)*J13 -> 1.4840708 | O13: =M13-N13 -> 11.415929
A14: 车位数 - V2G桩（个） | C14: 4 | F14: 增加车网互动功能费 | G14: 接入费用* | H14: 充电桩接入费用 | J14: 0.06 | K14: 40.5 | L14: 1 | M14: =L14*K14 -> 40.5 | N14: =M14/(1+J14)*J14 -> 2.2924528 | O14: =M14-N14 -> 38.207547
A15: 年有效天数（天） | C15: 350 | G15: 场站协调 | H15: 道闸、监控系统API打通 | J15: 0 | M15: 0 | N15: =M15/(1+J15)*J15 -> 0 | O15: =M15-N15 -> 0
A16: 充电桩折旧 | G16: 设计及手续 | H16: 设计及相关手续 | J16: 0 | M16: 10 | N16: =M16/(1+J16)*J16 -> 0 | O16: =M16-N16 -> 10
A17: 充电桩折旧年限 | C17: 8 | H17: 总计 | M17: =SUM(M4:M8,M10:M11,M13:M16) -> 358.4 | N17: =SUM(N4:N8,N10:N11,N13:N16) -> 32.833518 | O17: =SUM(O4:O8,O10:O11,O13:O16) -> 325.56648
A18: 残值率 | C18: 0
A19: 充电服务费收益 (含税) | D19: 客户端充放价差收益(含税) | G19: V2G充电桩返送电网收益(含税) | J19: 储能端返送电网收益(含税) | M19: 辅助服务市场(含税)
A20: 每天每车位平均充电车辆-超充（辆） | C20: 4 | D20: 262储能柜日充放次数 | F20: 1.5 | G20: 单车位返送度数(kwh) | I20: 40 | J20: 余电比例% | L20: =1-F31 -> 0 | M20: 年平均响应次数 | O20: 20
A21: 车均充电电量-超充（kwh） | C21: 40 | D21: 储能柜容量(kwh) | F21: =262*L10 -> 524 | G21: V2G桩 | I21: =C14 -> 4 | J21: 放电电价（元/kwh） | K21: 0.13 | M21: 每次响应电价（元/kwh） | N21: 0.13 | O21: 1
A22: 服务费-超充（元/kwh） | B22: 0.13 | C22: 0.4 | D22: 首年电池衰减率(SOH) | F22: 0.93 | G22: 场站每度服务费 | H22: 0.13 | I22: 0.8 | J22: 储能柜数量（pcs) | M22: 每次响应电量（kwh） | O22: 10
A23: 年服务费-超充（万元） | C23: =C11*C20*C21*C22*$C$15/10000 -> 8.96 | D23: 后续年充电桩衰减率 | G23: V2G场站收益(万元） | I23: =I20*I21*I22/10000*C15 -> 4.48 | J23: 储能柜容量（kwh） | M23: 辅助市场服务收益（万元） | O23: =O20*O22*O21/10000 -> 0.02
A24: 每天每车位平均充电车辆-快充（辆） | C24: 4 | D24: 年衰减情况 | F24: 线性衰减 | J24: 储能端返送电网收益（万元） | L24: =L20*L22*L23*L21/10000 -> 0
A25: 车均充电电量-快充（kwh） | C25: 40 | D25: 储能柜电池荷电状态(SOC) | F25: 0.85
A26: 服务费-快充（元/kwh） | B26: 0.13 | C26: 0.4 | D26: 电池充放电效率(RTE) | F26: 0.8
A27: 年服务费-快充（万元） | C27: =C12*C24*C25*C26*$C$15/10000 -> 49.28 | D27: 储能柜充电电量(kwh) | F27: =F21*F20*F22*F25*F26^0.5 -> 555.73713
A28: 每天每车位平均充电车辆-慢充（辆） | D28: 储能柜放电电量(kwh) | F28: =F27*F26 -> 444.5897
A29: 车均充电电量-慢充（kwh） | D29: 客户端充电电费(国网电价峰值/包头两月） | E29: 0.13 | F29: 0.77
A30: 服务费-慢充（元/kwh） | B30: 0.13 | D30: 客户端使用储能柜充电成本(国网电价谷值/包头两月） | E30: 0.13 | F30: 0.35
A31: 年服务费-慢充（万元） | C31: =C13*C28*C29*C30*$C$15/10000 -> 0 | D31: 使用比例 | F31: 1
A32: 每天每车位平均充电车辆-V2G（辆） | C32: 4 | D32: 首年充放价差收益(万元） | E32: 0.13 | F32: =(F28*F29-F30*F27)*C15/10000 -> 5.1739127
A33: 车均充电电量-V2G（kwh） | C33: 40
A34: 服务费-V2G（元/kwh） | B34: 0.13 | C34: 0.4
A35: 年服务费-V2G（万元） | C35: =C14*C32*C33*C34*$C$15/10000 -> 8.96
A36: 日总充电电量(kwh) | C36: =C20*C11*C21+C24*C25*C12+C32*C14*C33 -> 4800
A37: 充电桩年运维成本(含税）
A38: 充电桩巡检费 | B38: 0.06 | C38: =Opex清单!D2 -> 0.7
A39: 充电桩每年运维费 | B39: 0.06 | C39: =Opex清单!D3 -> 3
A40: 运维增长比例 | C40: 0.01
...

Sheet 储能SOH
E4: 电池衰减
D5: 1 | E5: 0.93349612
D6: 2 | E6: 0.9064211
D7: 3 | E7: 0.88357214
D8: 4 | E8: 0.86304747
D9: 5 | E9: 0.84406811
D10: 6 | E10: 0.82622194
D11: 7 | E11: 0.80922941
D12: 8 | E12: 0.7929244
D13: 9 | E13: 0.77719171
D14: 10 | E14: 0.76194482
D15: 11 | E15: 0.74711707
D16: 12 | E16: 0.73263935
... D19: 15 | E19: 0.69092982

Sheet 利润表
A1: 利润表
A3: 项目 | B3: T0 | C3: 1 | D3: 2 | E3: 3 | F3: 4 | G3: 5 | H3: 6 | I3: 7 | J3: 8 | K3: 9 | L3: 10
A5: 1.充电服务费收益(万元) | C5: =输入!C23/(1+输入!$B$22)+输入!C27/(1+输入!$B$26)+输入!C31/(1+输入!$B$30)+输入!C35/(1+输入!$B$34) -> 59.469027 | D5: =IF(D$3>输入!$C$9,0,C5) -> 59.469027 | E5: =IF(E$3>输入!$C$9,0,D5) -> 59.469027 | F5: =IF(F$3>输入!$C$9,0,E5) -> 59.469027 | G5: =IF(G$3>输入!$C$9,0,F5) -> 59.469027 | H5: =IF(H$3>输入!$C$9,0,G5) -> 59.469027 | I5: =IF(I$3>输入!$C$9,0,H5) -> 59.469027 | J5: =IF(J$3>输入!$C$9,0,I5) -> 59.469027 | K5: =IF(K$3>输入!$C$9,0,J5) -> 0 | L5: =IF(L$3>输入!$C$9,0,K5) -> 0
A6: 2.储能柜：客户端放电收益 | C6: =C$25*输入!$F$29/10000*输入!$F$31/(1+输入!$E$29) -> 10.603268 | D6: =IF(D$3>输入!$C$9,0,D$25*输入!$F$29/10000*输入!$F$31/(1+输入!$E$29)) -> 10.295732 | E6: =IF(E$3>输入!$C$9,0,E$25*输入!$F$29/10000*输入!$F$31/(1+输入!$E$29)) -> 10.036198 | F6: =IF(F$3>输入!$C$9,0,F$25*输入!$F$29/10000*输入!$F$31/(1+输入!$E$29)) -> 9.8030653 | G6: =IF(G$3>输入!$C$9,0,G$25*输入!$F$29/10000*输入!$F$31/(1+输入!$E$29)) -> 9.5874851 | H6: =IF(H$3>输入!$C$9,0,H$25*输入!$F$29/10000*输入!$F$31/(1+输入!$E$29)) -> 9.3847765 | I6: =IF(I$3>输入!$C$9,0,I$25*输入!$F$29/10000*输入!$F$31/(1+输入!$E$29)) -> 9.1917641 | J6: =IF(J$3>输入!$C$9,0,J$25*输入!$F$29/10000*输入!$F$31/(1+输入!$E$29)) -> 9.0065609 | K6: =IF(K$3>输入!$C$9,0,K$25*输入!$F$29/10000*输入!$F$31/(1+输入!$E$29)) -> 0 | L6: =IF(L$3>输入!$C$9,0,L$25*输入!$F$29/10000*输入!$F$31/(1+输入!$E$29)) -> 0
A7: 3.储能柜：送电网放电收益 | C7: =C$24*输入!$F$29/10000*(1-输入!$F$31)/(1+输入!$K$21) -> 0 | D7: =IF(D$3>输入!$C$9,0,D$24*输入!$F$29/10000*(1-输入!$F$31)/(1+输入!$K$21)) -> 0 | E7: =IF(E$3>输入!$C$9,0,E$24*输入!$F$29/10000*(1-输入!$F$31)/(1+输入!$K$21)) -> 0 | F7: =IF(F$3>输入!$C$9,0,F$24*输入!$F$29/10000*(1-输入!$F$31)/(1+输入!$K$21)) -> 0 | G7: =IF(G$3>输入!$C$9,0,G$24*输入!$F$29/10000*(1-输入!$F$31)/(1+输入!$K$21)) -> 0 | H7: =IF(H$3>输入!$C$9,0,H$24*输入!$F$29/10000*(1-输入!$F$31)/(1+输入!$K$21)) -> 0 | I7: =IF(I$3>输入!$C$9,0,I$24*输入!$F$29/10000*(1-输入!$F$31)/(1+输入!$K$21)) -> 0 | J7: =IF(J$3>输入!$C$9,0,J$24*输入!$F$29/10000*(1-输入!$F$31)/(1+输入!$K$21)) -> 0 | K7: =IF(K$3>输入!$C$9,0,K$24*输入!$F$29/10000*(1-输入!$F$31)/(1+输入!$K$21)) -> 0 | L7: =IF(L$3>输入!$C$9,0,L$24*输入!$F$29/10000*(1-输入!$F$31)/(1+输入!$K$21)) -> 0
A8: 4.V2G充电桩返送电网收益 | C8: =输入!$I$23/(1+输入!$H$22) -> 3.9646018 | D8: =IF(D$3>输入!$C$9,0,输入!$I$23/(1+输入!$H$22)) -> 3.9646018 | E8: =IF(E$3>输入!$C$9,0,输入!$I$23/(1+输入!$H$22)) -> 3.9646018 | F8: =IF(F$3>输入!$C$9,0,输入!$I$23/(1+输入!$H$22)) -> 3.9646018 | G8: =IF(G$3>输入!$C$9,0,输入!$I$23/(1+输入!$H$22)) -> 3.9646018 | H8: =IF(H$3>输入!$C$9,0,输入!$I$23/(1+输入!$H$22)) -> 3.9646018 | I8: =IF(I$3>输入!$C$9,0,输入!$I$23/(1+输入!$H$22)) -> 3.9646018 | J8: =IF(J$3>输入!$C$9,0,输入!$I$23/(1+输入!$H$22)) -> 3.9646018 | K8: =IF(K$3>输入!$C$9,0,输入!$I$23/(1+输入!$H$22)) -> 0 | L8: =IF(L$3>输入!$C$9,0,输入!$I$23/(1+输入!$H$22)) -> 0
A9: 5.辅助服务市场 | C9: =输入!$O$23/(1+输入!$N$21) -> 0.017699115 | D9: =IF(D$3>输入!$C$9,0,输入!$O$23/(1+输入!$N$21)) -> 0.017699115 | E9: =IF(E$3>输入!$C$9,0,输入!$O$23/(1+输入!$N$21)) -> 0.017699115 | F9: =IF(F$3>输入!$C$9,0,输入!$O$23/(1+输入!$N$21)) -> 0.017699115 | G9: =IF(G$3>输入!$C$9,0,输入!$O$23/(1+输入!$N$21)) -> 0.017699115 | H9: =IF(H$3>输入!$C$9,0,输入!$O$23/(1+输入!$N$21)) -> 0.017699115 | I9: =IF(I$3>输入!$C$9,0,输入!$O$23/(1+输入!$N$21)) -> 0.017699115 | J9: =IF(J$3>输入!$C$9,0,输入!$O$23/(1+输入!$N$21)) -> 0.017699115 | K9: =IF(K$3>输入!$C$9,0,输入!$O$23/(1+输入!$N$21)) -> 0 | L9: =IF(L$3>输入!$C$9,0,输入!$O$23/(1+输入!$N$21)) -> 0
A10: 营业收入合计 | C10: =SUM(C5:C9) -> 74.054595 | D10: =SUM(D5:D9) -> 73.747059 | E10: =SUM(E5:E9) -> 73.487526 | F10: =SUM(F5:F9) -> 73.254393 | G10: =SUM(G5:G9) -> 73.038813 | H10: =SUM(H5:H9) -> 72.836104 | I10: =SUM(I5:I9) -> 72.643092 | J10: =SUM(J5:J9) -> 72.457888 | ... L10: =SUM(L5:L9) -> 0
A12: 1.储能柜充电成本 | C12: =C$24*输入!$F$30/10000/(1+输入!$E$30) -> 6.0245839 | D12: =IF(D$3>输入!$C$9,0,D$24*输入!$F$30/10000/(1+输入!$E$30)) -> 5.8498475 | E12: =IF(E$3>输入!$C$9,0,E$24*输入!$F$30/10000/(1+输入!$E$30)) -> 5.7023853 | F12: =IF(F$3>输入!$C$9,0,F$24*输入!$F$30/10000/(1+输入!$E$30)) -> 5.5699235 | G12: =IF(G$3>输入!$C$9,0,G$24*输入!$F$30/10000/(1+输入!$E$30)) -> 5.4474347 | H12: =IF(H$3>输入!$C$9,0,H$24*输入!$F$30/10000/(1+输入!$E$30)) -> 5.3322594 | I12: =IF(I$3>输入!$C$9,0,I$24*输入!$F$30/10000/(1+输入!$E$30)) -> 5.2225932 | J12: =IF(J$3>输入!$C$9,0,J$24*输入!$F$30/10000/(1+输入!$E$30)) -> 5.1173642 | K12: =IF(K$3>输入!$C$9,0,K$24*输入!$F$30/10000/(1+输入!$E$30)) -> 0 | L12: =IF(L$3>输入!$C$9,0,L$24*输入!$F$30/10000/(1+输入!$E$30)) -> 0
A13: 2.折旧费用 | C13: =IF(C$3<=输入!$C$17,输入!$O$17/输入!$C$17*(1-输入!$C$18),0) -> 40.69581 | D13: =IF(D$3>输入!$C$9,0,输入!$O$17/输入!$C$17*(1-输入!$C$18)) -> 40.69581 | E13: =IF(E$3>输入!$C$9,0,输入!$O$17/输入!$C$17*(1-输入!$C$18)) -> 40.69581 | F13: =IF(F$3>输入!$C$9,0,输入!$O$17/输入!$C$17*(1-输入!$C$18)) -> 40.69581 | G13: =IF(G$3>输入!$C$9,0,输入!$O$17/输入!$C$17*(1-输入!$C$18)) -> 40.69581 | H13: =IF(H$3>输入!$C$9,0,输入!$O$17/输入!$C$17*(1-输入!$C$18)) -> 40.69581 | I13: =IF(I$3>输入!$C$9,0,输入!$O$17/输入!$C$17*(1-输入!$C$18)) -> 40.69581 | J13: =IF(J$3>输入!$C$9,0,输入!$O$17/输入!$C$17*(1-输入!$C$18)) -> 40.69581 | K13: =IF(K$3>输入!$C$9,0,输入!$O$17/输入!$C$17*(1-输入!$C$18)) -> 0 | L13: =IF(L$3>输入!$C$9,0,输入!$O$17/输入!$C$17*(1-输入!$C$18)) -> 0
A14: 3.运营费用 | C14: =C29 -> 14.594473 | D14: =IF(D$3>输入!$C$9,0,D29) -> 14.876548 | E14: =IF(E$3>输入!$C$9,0,E29) -> 15.171533 | F14: =IF(F$3>输入!$C$9,0,F29) -> 15.480059 | G14: =IF(G$3>输入!$C$9,0,G29) -> 15.802791 | H14: =IF(H$3>输入!$C$9,0,H29) -> 16.140429 | I14: =IF(I$3>输入!$C$9,0,I29) -> 16.493705 | J14: =IF(J$3>输入!$C$9,0,J29) -> 16.863388 | K14: =IF(K$3>输入!$C$9,0,K29) -> 0 | L14: =IF(L$3>输入!$C$9,0,L29) -> 0
A15: 4.附加税 | C15: =税务计算!C28 -> 0 | D15: =税务计算!D28 -> 0 | E15: =税务计算!E28 -> 0 | F15: =税务计算!F28 -> 0 | G15: =税务计算!G28 -> 0.64087681 | H15: =税务计算!H28 -> 0.89791023 | I15: =税务计算!I28 -> 0.89151413 | J15: =税务计算!J28 -> 0.88491883 | ... L15: =税务计算!L28 -> 0
A16: 营业成本合计 | C16: =C13+C14+C15+C12 -> 61.314867 | D16: =D13+D14+D15+D12 -> 61.422206 | E16: =E13+E14+E15+E12 -> 61.569728 | F16: =F13+F14+F15+F12 -> 61.745792 | G16: =G13+G14+G15+G12 -> 62.586913 | H16: =H13+H14+H15+H12 -> 63.066409 | I16: =I13+I14+I15+I12 -> 63.303622 | J16: =J13+J14+J15+J12 -> 63.561481 | ... L16: =L13+L14+L15+L12 -> 0
A18: 三、税前利润(EBT) | C18: =C10-C16 -> 12.739728 | D18: =D10-D16 -> 12.324853 | E18: =E10-E16 -> 11.917797 | F18: =F10-F16 -> 11.5086 | G18: =G10-G16 -> 10.451899 | H18: =H10-H16 -> 9.7696949 | I18: =I10-I16 -> 9.3394691 | J18: =J10-J16 -> 8.8964073 | ... L18: =L10-L16 -> 0
A19: 四、所得税费用 | C19: =税务计算!C40 -> 0 | D19: =税务计算!D40 -> 0 | E19: =税务计算!E40 -> 0 | F19: =税务计算!F40 -> 1.438575 | G19: =税务计算!G40 -> 1.3064874 | H19: =税务计算!H40 -> 1.2212119 | I19: =税务计算!I40 -> 2.3348673 | J19: =税务计算!J40 -> 2.2241018 | ... L19: =税务计算!L40 -> 0
A20: 五、净利润 | C20: =C18-C19 -> 12.739728 | D20: =D18-D19 -> 12.324853 | E20: =E18-E19 -> 11.917797 | F20: =F18-F19 -> 10.070025 | G20: =G18-G19 -> 9.1454119 | H20: =H18-H19 -> 8.548483 | I20: =I18-I19 -> 7.0046018 | J20: =J18-J19 -> 6.6723055 | ... L20: =L18-L19 -> 0
A23: 附表1：
A24: 储能柜充电电量(kwh) | C24: =输入!$F$27*输入!$C$15 -> 194508 | D24: =C24/C$26*D$26 -> 188866.51 | E24: =D24/D$26*E$26 -> 184105.58 | F24: =E24/E$26*F$26 -> 179828.96 | G24: =F24/F$26*G$26 -> 175874.32 | H24: =G24/G$26*H$26 -> 172155.8 | I24: =H24/H$26*I$26 -> 168615.15 | J24: =I24/I$26*J$26 -> 165217.76 | K24: =J24/J$26*K$26 -> 161939.61 | L24: =K24/K$26*L$26 -> 158762.69
A25: 储能柜放电电量 | C25: =输入!$F$28*输入!$C$15 -> 155606.4 | D25: =C25/C$26*D$26 -> 151093.21 | E25: =D25/D$26*E$26 -> 147284.47 | F25: =E25/E$26*F$26 -> 143863.17 | G25: =F25/F$26*G$26 -> 140699.46 | H25: =G25/G$26*H$26 -> 137724.64 | I25: =H25/H$26*I$26 -> 134892.12 | J25: =I25/I$26*J$26 -> 132174.21 | K25: =J25/J$26*K$26 -> 129551.69 | L25: =K25/K$26*L$26 -> 127010.16
A26: SOH | C26: {=TRANSPOSE(储能SOH!E5:E19)} -> 0.93349612 | D26: 0.9064211 | E26: 0.88357214 | F26: 0.86304747 | G26: 0.84406811 | H26: 0.82622194 | I26: 0.80922941 | J26: 0.7929244 | K26: 0.77719171 | L26: 0.76194482
A28: 附表2：
A29: 运维费(不含税) | C29: =SUM(C30:C41) -> 14.594473 | D29: =SUM(D30:D41) -> 14.876548 | E29: =SUM(E30:E41) -> 15.171533 | F29: =SUM(F30:F41) -> 15.480059 | G29: =SUM(G30:G41) -> 15.802791 | H29: =SUM(H30:H41) -> 16.140429 | I29: =SUM(I30:I41) -> 16.493705 | J29: =SUM(J30:J41) -> 16.863388 | ... L29: =SUM(L30:L41) -> 17.655247
A30: 充电桩巡检费 | C30: =输入!C$38/(1+输入!$B$38) -> 0.66037736 | D30: =C30 -> 0.66037736 | E30: =D30 -> 0.66037736 | F30: =E30 -> 0.66037736 | G30: =F30 -> 0.66037736 | H30: =G30 -> 0.66037736 | I30: =H30 -> 0.66037736 | J30: =I30 -> 0.66037736 | K30: =J30 -> 0.66037736 | L30: =K30 -> 0.66037736
A31: 充电桩每年运维费 | C31: =输入!$C$39/(1+输入!$B$39) -> 2.8301887 | D31: =C31 -> 2.8301887 | E31: =D31 -> 2.8301887 | F31: =E31 -> 2.8301887 | G31: =F31 -> 2.8301887 | H31: =G31 -> 2.8301887 | I31: =H31 -> 2.8301887 | J31: =I31 -> 2.8301887 | K31: =J31 -> 2.8301887 | L31: =K31 -> 2.8301887
A32: 充电桩运营人工 | C32: =输入!$C$41/(1+输入!$B$41) -> 2 | D32: =C32*(1+输入!$C$40) -> 2.02 | E32: =D32*(1+输入!$C$40) -> 2.0402 | F32: =E32*(1+输入!$C$40) -> 2.060602 | G32: =F32*(1+输入!$C$40) -> 2.081208 | H32: =G32*(1+输入!$C$40) -> 2.1020201 | I32: =H32*(1+输入!$C$40) -> 2.1230403 | J32: =I32*(1+输入!$C$40) -> 2.1442707 | K32: =J32*(1+输入!$C$40) -> 2.1657134 | L32: =K32*(1+输入!$C$40) -> 2.1873705
A33: 充电桩保险费 | C33: =输入!$C$42/(1+输入!$B$42) -> 0.24056604 | D33: =C33 -> 0.24056604 | E33: =D33 -> 0.24056604 | F33: =E33 -> 0.24056604 | G33: =F33 -> 0.24056604 | H33: =G33 -> 0.24056604 | I33: =H33 -> 0.24056604 | J33: =I33 -> 0.24056604 | K33: =J33 -> 0.24056604 | L33: =K33 -> 0.24056604
A34: 智慧充电运营运维管理系统费* | C34: =输入!$C$43/(1+输入!$B$43) -> 0.94339623 | D34: =C34 -> 0.94339623 | E34: =D34 -> 0.94339623 | F34: =E34 -> 0.94339623 | G34: =F34 -> 0.94339623 | H34: =G34 -> 0.94339623 | I34: =H34 -> 0.94339623 | J34: =I34 -> 0.94339623 | K34: =J34 -> 0.94339623 | L34: =K34 -> 0.94339623
A35: 光伏运维费 | C35: =输入!$C$44/(1+输入!$B$44) -> 0 | D35: =C35 -> 0 | E35: =D35 -> 0 | F35: =E35 -> 0 | G35: =F35 -> 0 | H35: =G35 -> 0 | I35: =H35 -> 0 | J35: =I35 -> 0 | K35: =J35 -> 0 | L35: =K35 -> 0
A36: 储能运维 | C36: =输入!$C$45/(1+输入!$B$45) -> 0.98867925 | D36: =C36*(1+输入!$C$46) -> 0.99856604 | E36: =D36*(1+输入!$C$46) -> 1.0085517 | F36: =E36*(1+输入!$C$46) -> 1.0186372 | G36: =F36*(1+输入!$C$46) -> 1.0288236 | H36: =G36*(1+输入!$C$46) -> 1.0391118 | I36: =H36*(1+输入!$C$46) -> 1.0495029 | J36: =I36*(1+输入!$C$46) -> 1.059998 | K36: =J36*(1+输入!$C$46) -> 1.070598 | L36: =K36*(1+输入!$C$46) -> 1.0813039
A37: 储能保险 | C37: =输入!$C$47/(1+输入!$B$47) -> 0.00069056604 | D37: =C37 -> 0.00069056604 | E37: =D37 -> 0.00069056604 | F37: =E37 -> 0.00069056604 | G37: =F37 -> 0.00069056604 | H37: =G37 -> 0.00069056604 | I37: =H37 -> 0.00069056604 | J37: =I37 -> 0.00069056604 | K37: =J37 -> 0.00069056604 | L37: =K37 -> 0.00069056604
A38: 储充微网系统* | C38: =输入!$C$48/(1+输入!$B$48) -> 1.8867925 | D38: =C38 -> 1.8867925 | E38: =D38 -> 1.8867925 | F38: =E38 -> 1.8867925 | G38: =F38 -> 1.8867925 | H38: =G38 -> 1.8867925 | I38: =H38 -> 1.8867925 | J38: =I38 -> 1.8867925 | K38: =J38 -> 1.8867925 | L38: =K38 -> 1.8867925
A39: 车位费 | C39: =输入!$C$49/(1+输入!$B$49) -> 0 | D39: =C39 -> 0 | E39: =D39 -> 0 | F39: =E39 -> 0 | G39: =F39 -> 0 | H39: =G39 -> 0 | I39: =H39 -> 0 | J39: =I39 -> 0 | K39: =J39 -> 0 | L39: =K39 -> 0
A40: 地图投放、检索 | C40: =输入!$C$50/(1+输入!$B$50) -> 0 | D40: =C40 -> 0 | E40: =D40 -> 0 | F40: =E40 -> 0 | G40: =F40 -> 0 | H40: =G40 -> 0 | I40: =H40 -> 0 | J40: =I40 -> 0 | K40: =J40 -> 0 | L40: =K40 -> 0
A41: 充电损耗 | C41: =输入!$C$51/(1+输入!$B$51) -> 5.043782 | D41: =C41*(1+输入!$C$52) -> 5.2959711 | E41: =D41*(1+输入!$C$52) -> 5.5607697 | F41: =E41*(1+输入!$C$52) -> 5.8388082 | G41: =F41*(1+输入!$C$52) -> 6.1307486 | H41: =G41*(1+输入!$C$52) -> 6.437286 | I41: =H41*(1+输入!$C$52) -> 6.7591503 | J41: =I41*(1+输入!$C$52) -> 7.0971078 | K41: =J41*(1+输入!$C$52) -> 7.4519632 | L41: =K41*(1+输入!$C$52) -> 7.8245614
A43: 运维费进项税 | C43: =SUM(C44:C55) -> 1.1087331 | D43: =SUM(D44:D55) -> 1.1421109 | E43: =SUM(E44:E55) -> 1.1771338 | F43: =SUM(F44:F55) -> 1.213884 | G43: =SUM(G44:G55) -> 1.2524474 | H43: =SUM(H44:H55) -> 1.2929146 | I43: =SUM(I44:I55) -> 1.3353804 | J43: =SUM(J44:J55) -> 1.3799446 | ... L43: =SUM(L44:L55) -> 1.4757919
A44: 充电桩巡检费 | C44: =输入!C$38/(1+输入!$B$38)*输入!$B$38 -> 0.039622642 | D44: =C44 -> 0.039622642 | E44: =D44 -> 0.039622642 | F44: =E44 -> 0.039622642 | G44: =F44 -> 0.039622642 | H44: =G44 -> 0.039622642 | I44: =H44 -> 0.039622642 | J44: =I44 -> 0.039622642 | K44: =J44 -> 0.039622642 | L44: =K44 -> 0.039622642
A45: 充电桩每年运维费 | C45: =输入!$C$39/(1+输入!$B$39)*输入!$B$39 -> 0.16981132 | D45: =C45 -> 0.16981132 | E45: =D45 -> 0.16981132 | F45: =E45 -> 0.16981132 | G45: =F45 -> 0.16981132 | H45: =G45 -> 0.16981132 | I45: =H45 -> 0.16981132 | J45: =I45 -> 0.16981132 | K45: =J45 -> 0.16981132 | L45: =K45 -> 0.16981132
A46: 充电桩运营人工 | C46: =输入!$C$41/(1+输入!$B$41)*输入!$B$41 -> 0 | D46: =C46*(1+输入!$C$40) -> 0 | E46: =D46*(1+输入!$C$40) -> 0 | F46: =E46*(1+输入!$C$40) -> 0 | G46: =F46*(1+输入!$C$40) -> 0 | H46: =G46*(1+输入!$C$40) -> 0 | I46: =H46*(1+输入!$C$40) -> 0 | J46: =I46*(1+输入!$C$40) -> 0 | K46: =J46*(1+输入!$C$40) -> 0 | L46: =K46*(1+输入!$C$40) -> 0
A47: 充电桩保险费 | C47: =输入!$C$42/(1+输入!$B$42)*输入!$B$42 -> 0.014433962 | D47: =C47 -> 0.014433962 | E47: =D47 -> 0.014433962 | F47: =E47 -> 0.014433962 | G47: =F47 -> 0.014433962 | H47: =G47 -> 0.014433962 | I47: =H47 -> 0.014433962 | J47: =I47 -> 0.014433962 | K47: =J47 -> 0.014433962 | L47: =K47 -> 0.014433962
A48: 智慧充电运营运维管理系统费* | C48: =输入!$C$43/(1+输入!$B$43)*输入!$B$43 -> 0.056603774 | D48: =C48 -> 0.056603774 | E48: =D48 -> 0.056603774 | F48: =E48 -> 0.056603774 | G48: =F48 -> 0.056603774 | H48: =G48 -> 0.056603774 | I48: =H48 -> 0.056603774 | J48: =I48 -> 0.056603774 | K48: =J48 -> 0.056603774 | L48: =K48 -> 0.056603774
...

Sheet 税务计算
A1: 税务计算表
A3: 项目 | B3: T0 | C3: 1 | D3: 2 | E3: 3 | F3: 4 | G3: 5 | H3: 6 | I3: 7 | J3: 8 | K3: 9 | L3: 10
A4: 一、销项税额
A5: 1.充电服务费收益(万元) | C5: =利润表!C5*输入!$B$22 -> 7.7309735 | D5: =利润表!D5*输入!$B$22 -> 7.7309735 | E5: =利润表!E5*输入!$B$22 -> 7.7309735 | F5: =利润表!F5*输入!$B$22 -> 7.7309735 | G5: =利润表!G5*输入!$B$22 -> 7.7309735 | H5: =利润表!H5*输入!$B$22 -> 7.7309735 | I5: =利润表!I5*输入!$B$22 -> 7.7309735 | J5: =利润表!J5*输入!$B$22 -> 7.7309735 | ... L5: =利润表!L5*输入!$B$22 -> 0
A6: 2.储能柜：客户端放电收益 | C6: =利润表!C6*输入!$E$29 -> 1.3784248 | D6: =利润表!D6*输入!$E$29 -> 1.3384451 | E6: =利润表!E6*输入!$E$29 -> 1.3047058 | F6: =利润表!F6*输入!$E$29 -> 1.2743985 | G6: =利润表!G6*输入!$E$29 -> 1.2463731 | H6: =利润表!H6*输入!$E$29 -> 1.220021 | I6: =利润表!I6*输入!$E$29 -> 1.1949293 | J6: =利润表!J6*输入!$E$29 -> 1.1708529 | ... L6: =利润表!L6*输入!$E$29 -> 0
A7: 3.储能柜：送电网放电收益 | C7: =利润表!C7*输入!$K$21 -> 0 | D7: =利润表!D7*输入!$K$21 -> 0 | E7: =利润表!E7*输入!$K$21 -> 0 | F7: =利润表!F7*输入!$K$21 -> 0 | G7: =利润表!G7*输入!$K$21 -> 0 | H7: =利润表!H7*输入!$K$21 -> 0 | I7: =利润表!I7*输入!$K$21 -> 0 | J7: =利润表!J7*输入!$K$21 -> 0 | ... L7: =利润表!L7*输入!$K$21 -> 0
A8: 4.V2G充电桩返送电网收益 | C8: =利润表!C8*输入!$H$22 -> 0.51539823 | D8: =利润表!D8*输入!$H$22 -> 0.51539823 | E8: =利润表!E8*输入!$H$22 -> 0.51539823 | F8: =利润表!F8*输入!$H$22 -> 0.51539823 | G8: =利润表!G8*输入!$H$22 -> 0.51539823 | H8: =利润表!H8*输入!$H$22 -> 0.51539823 | I8: =利润表!I8*输入!$H$22 -> 0.51539823 | J8: =利润表!J8*输入!$H$22 -> 0.51539823 | ... L8: =利润表!L8*输入!$H$22 -> 0
A9: 5.辅助服务市场 | C9: =利润表!C9*输入!$N$21 -> 0.002300885 | D9: =利润表!D9*输入!$N$21 -> 0.002300885 | E9: =利润表!E9*输入!$N$21 -> 0.002300885 | F9: =利润表!F9*输入!$N$21 -> 0.002300885 | G9: =利润表!G9*输入!$N$21 -> 0.002300885 | H9: =利润表!H9*输入!$N$21 -> 0.002300885 | I9: =利润表!I9*输入!$N$21 -> 0.002300885 | J9: =利润表!J9*输入!$N$21 -> 0.002300885 | ... L9: =利润表!L9*输入!$N$21 -> 0
A10: 销项税合计 | C10: =C5+C6+C7+C8+C9 -> 9.6270974 | D10: =D5+D6+D7+D8+D9 -> 9.5871177 | E10: =E5+E6+E7+E8+E9 -> 9.5533783 | F10: =F5+F6+F7+F8+F9 -> 9.5230711 | G10: =G5+G6+G7+G8+G9 -> 9.4950456 | H10: =H5+H6+H7+H8+H9 -> 9.4686935 | I10: =I5+I6+I7+I8+I9 -> 9.4436019 | J10: =J5+J6+J7+J8+J9 -> 9.4195255 | ... L10: =L5+L6+L7+L8+L9 -> 0
A12: 二、进项税额
A13: T0CAPEX进项税 | B13: =输入!N17 -> 32.833518 | C13: 0 | D13: 0 | E13: 0 | F13: 0 | G13: 0 | H13: 0 | I13: 0 | J13: 0 | K13: 0 | L13: 0
A14: 储能柜电费进项税 | C14: =利润表!C12*输入!$E$30 -> 0.78319591 | D14: =利润表!D12*输入!$E$30 -> 0.76048018 | E14: =利润表!E12*输入!$E$30 -> 0.74131009 | F14: =利润表!F12*输入!$E$30 -> 0.72409005 | G14: =利润表!G12*输入!$E$30 -> 0.70816651 | H14: =利润表!H12*输入!$E$30 -> 0.69319372 | I14: =利润表!I12*输入!$E$30 -> 0.67893712 | J14: =利润表!J12*输入!$E$30 -> 0.66525734 | ... L14: =利润表!L12*输入!$E$30 -> 0
A15: 运营进项税 | B15: 0 | C15: =IF(C$3>输入!$C$9,0,利润表!C43) -> 1.1087331 | D15: =IF(D$3>输入!$C$9,0,利润表!D43) -> 1.1421109 | E15: =IF(E$3>输入!$C$9,0,利润表!E43) -> 1.1771338 | F15: =IF(F$3>输入!$C$9,0,利润表!F43) -> 1.213884 | G15: =IF(G$3>输入!$C$9,0,利润表!G43) -> 1.2524474 | H15: =IF(H$3>输入!$C$9,0,利润表!H43) -> 1.2929146 | I15: =IF(I$3>输入!$C$9,0,利润表!I43) -> 1.3353804 | J15: =IF(J$3>输入!$C$9,0,利润表!J43) -> 1.3799446 | ... L15: =IF(L$3>输入!$C$9,0,利润表!L43) -> 0
A16: 进项税合计 | B16: =B13+B15+B14 -> 32.833518 | C16: =C13+C15+C14 -> 1.891929 | D16: =D13+D15+D14 -> 1.9025911 | E16: =E13+E15+E14 -> 1.9184439 | F16: =F13+F15+F14 -> 1.937974 | G16: =G13+G15+G14 -> 1.9606139 | H16: =H13+H15+H14 -> 1.9861083 | I16: =I13+I15+I14 -> 2.0143175 | ... L16: =L13+L15+L14 -> 0
A18: 三、增值税计算
A19: 期初留抵税额 | B19: 0 | C19: =IF(C$3>输入!$C$9,0,B22) -> 32.833518 | D19: =IF(D$3>输入!$C$9,0,C22) -> 25.09835 | E19: =IF(E$3>输入!$C$9,0,D22) -> 17.413823 | F19: =IF(F$3>输入!$C$9,0,E22) -> 9.7788887 | G19: =IF(G$3>输入!$C$9,0,F22) -> 2.1937916 | H19: =IF(H$3>输入!$C$9,0,G22) -> 0 | I19: =IF(I$3>输入!$C$9,0,H22) -> 0 | J19: =IF(J$3>输入!$C$9,0,I22) -> 0 | ... L19: =IF(L$3>输入!$C$9,0,K22) -> 0
A20: 本期增加可抵扣进项税 | B20: =B16+B19 -> 32.833518 | C20: =C16+C19 -> 34.725447 | D20: =D16+D19 -> 27.000941 | E20: =E16+E19 -> 19.332267 | F20: =F16+F19 -> 11.716863 | G20: =G16+G19 -> 4.1544055 | H20: =H16+H19 -> 1.9861083 | I20: =I16+I19 -> 2.0143175 | ... L20: =L16+L19 -> 0
A21: 应交增值税 | B21: =MAX(0,B10-B20) -> 0 | C21: =MAX(0,C10-C20) -> 0 | D21: =MAX(0,D10-D20) -> 0 | E21: =MAX(0,E10-E20) -> 0 | F21: =MAX(0,F10-F20) -> 0 | G21: =MAX(0,G10-G20) -> 5.3406401 | H21: =MAX(0,H10-H20) -> 7.4825852 | I21: =MAX(0,I10-I20) -> 7.4292844 | ... L21: =MAX(0,L10-L20) -> 0
A22: 期末留抵税额 | B22: =MAX(0,B20-B10) -> 32.833518 | C22: =MAX(0,C20-C10) -> 25.09835 | D22: =MAX(0,D20-D10) -> 17.413823 | E22: =MAX(0,E20-E10) -> 9.7788887 | F22: =MAX(0,F20-F10) -> 2.1937916 | G22: =MAX(0,G20-G10) -> 0 | H22: =MAX(0,H20-H10) -> 0 | I22: =MAX(0,I20-I10) -> 0 | ... L22: =MAX(0,L20-L10) -> 0
A24: 四、附加税
A25: 城建税(7%) | B25: =B21*0.07 -> 0 | C25: =C21*0.07 -> 0 | D25: =D21*0.07 -> 0 | E25: =E21*0.07 -> 0 | F25: =F21*0.07 -> 0 | G25: =G21*0.07 -> 0.37384481 | H25: =H21*0.07 -> 0.52378097 | I25: =I21*0.07 -> 0.52004991 | ... L25: =L21*0.07 -> 0
A26: 教育费附加(3%) | B26: =B21*0.03 -> 0 | C26: =C21*0.03 -> 0 | D26: =D21*0.03 -> 0 | E26: =E21*0.03 -> 0 | F26: =F21*0.03 -> 0 | G26: =G21*0.03 -> 0.1602192 | H26: =H21*0.03 -> 0.22447756 | I26: =I21*0.03 -> 0.22287853 | ... L26: =L21*0.03 -> 0
A27: 地方教育附加(2%) | B27: =B21*0.02 -> 0 | C27: =C21*0.02 -> 0 | D27: =D21*0.02 -> 0 | E27: =E21*0.02 -> 0 | F27: =F21*0.02 -> 0 | G27: =G21*0.02 -> 0.1068128 | H27: =H21*0.02 -> 0.1496517 | I27: =I21*0.02 -> 0.14858569 | ... L27: =L21*0.02 -> 0
A28: 附加税合计 | B28: =B25+B26+B27 -> 0 | C28: =C25+C26+C27 -> 0 | D28: =D25+D26+D27 -> 0 | E28: =E25+E26+E27 -> 0 | F28: =F25+F26+F27 -> 0 | G28: =G25+G26+G27 -> 0.64087681 | H28: =H25+H26+H27 -> 0.89791023 | I28: =I25+I26+I27 -> 0.89151413 | ... L28: =L25+L26+L27 -> 0
A30: 五、企业所得税计算
A31: 税前利润(引用利润表) | B31: =利润表!B18 -> 0 | C31: =利润表!C18 -> 12.739728 | D31: =利润表!D18 -> 12.324853 | E31: =利润表!E18 -> 11.917797 | F31: =利润表!F18 -> 11.5086 | G31: =利润表!G18 -> 10.451899 | H31: =利润表!H18 -> 9.7696949 | I31: =利润表!I18 -> 9.3394691 | ... L31: =利润表!L18 -> 0
A32: 纳税调整前所得 | B32: =B31 -> 0 | C32: =C31 -> 12.739728 | D32: =D31 -> 12.324853 | E32: =E31 -> 11.917797 | F32: =F31 -> 11.5086 | G32: =G31 -> 10.451899 | H32: =H31 -> 9.7696949 | I32: =I31 -> 9.3394691 | ... L32: =L31 -> 0
A33: 未过期亏损 | B33: 0 | C33: =SUM(B35) -> 0 | D33: =SUM(B35:C35) -> 0 | E33: =SUM(B35:D35) -> 0 | F33: =SUM(B35:E35) -> 0 | G33: =SUM(B35:F35) -> 0 | H33: =SUM(C35:G35) -> 0 | I33: =SUM(D35:H35) -> 0 | J33: =SUM(E35:I35) -> 0 | K33: =SUM(F35:J35) -> 0 | L33: =SUM(G35:K35) -> 0
A34: 期初可弥补亏损(5年期内) | B34: =0 -> 0 | C34: =MIN(B37,C33) -> 0 | D34: =MIN(C37,D33) -> 0 | E34: =MIN(D37,E33) -> 0 | F34: =MIN(E37,F33) -> 0 | G34: =MIN(F37,G33) -> 0 | H34: =MIN(G37,H33) -> 0 | I34: =MIN(H37,I33) -> 0 | J34: =MIN(I37,J33) -> 0 | ... L34: =MIN(K37,L33) -> 0
A35: 加：当年新增亏损 | B35: =IF(B32<0,ABS(B32),0) -> 0 | C35: =IF(C32<0,ABS(C32),0) -> 0 | D35: =IF(D32<0,ABS(D32),0) -> 0 | E35: =IF(E32<0,ABS(E32),0) -> 0 | F35: =IF(F32<0,ABS(F32),0) -> 0 | G35: =IF(G32<0,ABS(G32),0) -> 0 | H35: =IF(H32<0,ABS(H32),0) -> 0 | I35: =IF(I32<0,ABS(I32),0) -> 0 | ... L35: =IF(L32<0,ABS(L32),0) -> 0
A36: 减：当年使用可弥补亏损 | B36: =MAX(0,MIN(B34,B32)) -> 0 | C36: =MAX(0,MIN(C34,C32)) -> 0 | D36: =MAX(0,MIN(D34,D32)) -> 0 | E36: =MAX(0,MIN(E34,E32)) -> 0 | F36: =MAX(0,MIN(F34,F32)) -> 0 | G36: =MAX(0,MIN(G34,G32)) -> 0 | H36: =MAX(0,MIN(H34,H32)) -> 0 | I36: =MAX(0,MIN(I34,I32)) -> 0 | ... L36: =MAX(0,MIN(L34,L32)) -> 0
A37: 期末可弥补亏损(5年期内) | B37: =B35+B34-B36 -> 0 | C37: =C35+C34-C36 -> 0 | D37: =D35+D34-D36 -> 0 | E37: =E35+E34-E36 -> 0 | F37: =F35+F34-F36 -> 0 | G37: =G35+G34-G36 -> 0 | H37: =H35+H34-H36 -> 0 | I37: =I35+I34-I36 -> 0 | ... L37: =L35+L34-L36 -> 0
A38: 应纳税所得额 | B38: =MAX(0,B32-B36) -> 0 | C38: =MAX(0,C32-C36) -> 12.739728 | D38: =MAX(0,D32-D36) -> 12.324853 | E38: =MAX(0,E32-E36) -> 11.917797 | F38: =MAX(0,F32-F36) -> 11.5086 | G38: =MAX(0,G32-G36) -> 10.451899 | H38: =MAX(0,H32-H36) -> 9.7696949 | I38: =MAX(0,I32-I36) -> 9.3394691 | ... L38: =MAX(0,L32-L36) -> 0
A39: 所得税率(25%，三免三减半） | B39: 0 | C39: 0 | D39: 0 | E39: 0 | F39: 0.125 | G39: 0.125 | H39: 0.125 | I39: 0.25 | J39: 0.25 | K39: 0.25 | L39: 0.25
A40: 应纳所得税额 | B40: =MAX(0,B38*B39) -> 0 | C40: =MAX(0,C38*C39) -> 0 | D40: =MAX(0,D38*D39) -> 0 | E40: =MAX(0,E38*E39) -> 0 | F40: =MAX(0,F38*F39) -> 1.438575 | G40: =MAX(0,G38*G39) -> 1.3064874 | H40: =MAX(0,H38*H39) -> 1.2212119 | I40: =MAX(0,I38*I39) -> 2.3348673 | ... L40: =MAX(0,L38*L39) -> 0

Sheet 现金流量表
A1: 现金流量表
A3: 项目 | B3: T0 | C3: 1 | D3: 2 | E3: 3 | F3: 4 | G3: 5 | H3: 6 | I3: 7 | J3: 8 | K3: 9 | L3: 10
A4: 一、经营活动产生的现金流量
A5: 销售商品、提供劳务收到的现金 | C5: =利润表!C10 -> 74.054595 | D5: =利润表!D10 -> 73.747059 | E5: =利润表!E10 -> 73.487526 | F5: =利润表!F10 -> 73.254393 | G5: =利润表!G10 -> 73.038813 | H5: =利润表!H10 -> 72.836104 | I5: =利润表!I10 -> 72.643092 | J5: =利润表!J10 -> 72.457888 | ... L5: =利润表!L10 -> 0
A6: 收到的增值税进项税返还 | C6: =MAX(0,税务计算!C10-税务计算!C16-税务计算!C21) -> 7.7351684 | D6: =MAX(0,税务计算!D10-税务计算!D16-税务计算!D21) -> 7.6845266 | E6: =MAX(0,税务计算!E10-税务计算!E16-税务计算!E21) -> 7.6349344 | F6: =MAX(0,税务计算!F10-税务计算!F16-税务计算!F21) -> 7.585097 | G6: =MAX(0,税务计算!G10-税务计算!G16-税务计算!G21) -> 2.1937916 | H6: =MAX(0,税务计算!H10-税务计算!H16-税务计算!H21) -> 0 | I6: =MAX(0,税务计算!I10-税务计算!I16-税务计算!I21) -> 0 | J6: =MAX(0,税务计算!J10-税务计算!J16-税务计算!J21) -> 0 | ... L6: =MAX(0,税务计算!L10-税务计算!L16-税务计算!L21) -> 0
A7: 经营活动现金流入小计 | C7: =C5+C6 -> 81.789764 | D7: =D5+D6 -> 81.431586 | E7: =E5+E6 -> 81.12246 | F7: =F5+F6 -> 80.83949 | G7: =G5+G6 -> 75.232604 | H7: =H5+H6 -> 72.836104 | I7: =I5+I6 -> 72.643092 | J7: =J5+J6 -> 72.457888 | ... L7: =L5+L6 -> 0
A8: 支付的各项税费（附加税） | C8: =-税务计算!C28 -> 0 | D8: =-税务计算!D28 -> 0 | E8: =-税务计算!E28 -> 0 | F8: =-税务计算!F28 -> 0 | G8: =-税务计算!G28 -> -0.64087681 | H8: =-税务计算!H28 -> -0.89791023 | I8: =-税务计算!I28 -> -0.89151413 | J8: =-税务计算!J28 -> -0.88491883 | ... L8: =-税务计算!L28 -> 0
A9: 支付的各项税费（所得税） | C9: =-税务计算!C40 -> 0 | D9: =-税务计算!D40 -> 0 | E9: =-税务计算!E40 -> 0 | F9: =-税务计算!F40 -> -1.438575 | G9: =-税务计算!G40 -> -1.3064874 | H9: =-税务计算!H40 -> -1.2212119 | I9: =-税务计算!I40 -> -2.3348673 | J9: =-税务计算!J40 -> -2.2241018 | ... L9: =-税务计算!L40 -> 0
A10: 支付充电电费 | C10: =-利润表!C12 -> -6.0245839 | D10: =-利润表!D12 -> -5.8498475 | E10: =-利润表!E12 -> -5.7023853 | F10: =-利润表!F12 -> -5.5699235 | G10: =-利润表!G12 -> -5.4474347 | H10: =-利润表!H12 -> -5.3322594 | I10: =-利润表!I12 -> -5.2225932 | J10: =-利润表!J12 -> -5.1173642 | ... L10: =-利润表!L12 -> 0
A11: 支付其他与经营活动有关的现金 | C11: =-利润表!C14 -> -14.594473 | D11: =-利润表!D14 -> -14.876548 | E11: =-利润表!E14 -> -15.171533 | F11: =-利润表!F14 -> -15.480059 | G11: =-利润表!G14 -> -15.802791 | H11: =-利润表!H14 -> -16.140429 | I11: =-利润表!I14 -> -16.493705 | J11: =-利润表!J14 -> -16.863388 | ... L11: =-利润表!L14 -> 0
A12: 经营活动现金流出小计 | C12: =C8+C9+C11+C10 -> -20.619057 | D12: =D8+D9+D11+D10 -> -20.726396 | E12: =E8+E9+E11+E10 -> -20.873918 | F12: =F8+F9+F11+F10 -> -22.488557 | G12: =G8+G9+G11+G10 -> -23.19759 | H12: =H8+H9+H11+H10 -> -23.591811 | I12: =I8+I9+I11+I10 -> -24.942679 | J12: =J8+J9+J11+J10 -> -25.089773 | ... L12: =L8+L9+L11+L10 -> 0
A13: 经营活动产生的现金流量净额 | C13: =C12+C7 -> 61.170707 | D13: =D12+D7 -> 60.70519 | E13: =E12+E7 -> 60.248542 | F13: =F12+F7 -> 58.350933 | G13: =G12+G7 -> 52.035014 | H13: =H12+H7 -> 49.244293 | I13: =I12+I7 -> 47.700412 | J13: =J12+J7 -> 47.368116 | ... L13: =L12+L7 -> 0
A15: 二、投资活动产生的现金流量
A16: 收回投资收到的现金 | B16: =IF(B3=输入!$C$17,输入!$O$17*输入!$C$18,0) -> 0 | C16: =IF(C3=输入!$C$17,输入!$O$17*输入!$C$18,0) -> 0 | D16: =IF(D3=输入!$C$17,输入!$O$17*输入!$C$18,0) -> 0 | E16: =IF(E3=输入!$C$17,输入!$O$17*输入!$C$18,0) -> 0 | F16: =IF(F3=输入!$C$17,输入!$O$17*输入!$C$18,0) -> 0 | G16: =IF(G3=输入!$C$17,输入!$O$17*输入!$C$18,0) -> 0 | H16: =IF(H3=输入!$C$17,输入!$O$17*输入!$C$18,0) -> 0 | I16: =IF(I3=输入!$C$17,输入!$O$17*输入!$C$18,0) -> 0 | ... L16: =IF(L3=输入!$C$17,输入!$O$17*输入!$C$18,0) -> 0
A17: 投资活动现金流入小计 | B17: =B16 -> 0 | C17: =C16 -> 0 | D17: =D16 -> 0 | E17: =E16 -> 0 | F17: =F16 -> 0 | G17: =G16 -> 0 | H17: =H16 -> 0 | I17: =I16 -> 0 | ... L17: =L16 -> 0
A18: 购建固定资产、无形资产支付的现金 | B18: =-输入!$M$17 -> -358.4
A19: 投资活动现金流出小计 | B19: =B18 -> -358.4 | C19: =C18 -> 0 | D19: =D18 -> 0 | E19: =E18 -> 0 | F19: =F18 -> 0 | G19: =G18 -> 0 | H19: =H18 -> 0 | I19: =I18 -> 0 | ... L19: =L18 -> 0
A20: 投资活动产生的现金流量净额 | B20: =B19+B17 -> -358.4 | C20: =C19+C17 -> 0 | D20: =D19+D17 -> 0 | E20: =E19+E17 -> 0 | F20: =F19+F17 -> 0 | G20: =G19+G17 -> 0 | H20: =H19+H17 -> 0 | I20: =I19+I17 -> 0 | ... L20: =L19+L17 -> 0
A22: 三、筹资活动产生的现金流量
A23: 吸收投资收到的现金
A24: 筹资活动现金流入小计 | B24: =B23 -> 0 | C24: =C23 -> 0 | D24: =D23 -> 0 | E24: =E23 -> 0 | F24: =F23 -> 0 | G24: =G23 -> 0 | H24: =H23 -> 0 | I24: =I23 -> 0 | ... L24: =L23 -> 0
A25: 分配股利、利润支付的现金
A26: 筹资活动现金流出小计 | B26: =B25 -> 0 | C26: =C25 -> 0 | D26: =D25 -> 0 | E26: =E25 -> 0 | F26: =F25 -> 0 | G26: =G25 -> 0 | H26: =H25 -> 0 | I26: =I25 -> 0 | ... L26: =L25 -> 0
A27: 筹资活动产生的现金流量净额 | B27: =B24+B26 -> 0 | C27: =C24+C26 -> 0 | D27: =D24+D26 -> 0 | E27: =E24+E26 -> 0 | F27: =F24+F26 -> 0 | G27: =G24+G26 -> 0 | H27: =H24+H26 -> 0 | I27: =I24+I26 -> 0 | ... L27: =L24+L26 -> 0
A29: 四、净现金流
A30: 期初现金余额 | B30: 0 | C30: =IF(C$3>输入!$C$9,0,B32) -> -358.4 | D30: =IF(D$3>输入!$C$9,0,C32) -> -297.22929 | E30: =IF(E$3>输入!$C$9,0,D32) -> -236.5241 | F30: =IF(F$3>输入!$C$9,0,E32) -> -176.27556 | G30: =IF(G$3>输入!$C$9,0,F32) -> -117.92463 | H30: =IF(H$3>输入!$C$9,0,G32) -> -65.889615 | I30: =IF(I$3>输入!$C$9,0,H32) -> -16.645322 | J30: =IF(J$3>输入!$C$9,0,I32) -> 31.05509 | ... L30: =IF(L$3>输入!$C$9,0,K32) -> 0
A31: 净现金流 | B31: =B13+B20+B27 -> -358.4 | C31: =C13+C20+C27 -> 61.170707 | D31: =D13+D20+D27 -> 60.70519 | E31: =E13+E20+E27 -> 60.248542 | F31: =F13+F20+F27 -> 58.350933 | G31: =G13+G20+G27 -> 52.035014 | H31: =H13+H20+H27 -> 49.244293 | I31: =I13+I20+I27 -> 47.700412 | ... L31: =L13+L20+L27 -> 0
A32: 期末现金余额 | B32: =B30+B31 -> -358.4 | C32: =C30+C31 -> -297.22929 | D32: =D30+D31 -> -236.5241 | E32: =E30+E31 -> -176.27556 | F32: =F30+F31 -> -117.92463 | G32: =G30+G31 -> -65.889615 | H32: =H30+H31 -> -16.645322 | I32: =I30+I31 -> 31.05509 | ... L32: =L30+L31 -> 0
A34: 折现日期 | B34: =输入!$C$5 -> 46265 | C34: =输入!$C$7 -> 46388 | D34: =DATE(YEAR(C34)+1,1,1) -> 46753 | E34: =DATE(YEAR(D34)+1,1,1) -> 47119 | F34: =DATE(YEAR(E34)+1,1,1) -> 47484 | G34: =DATE(YEAR(F34)+1,1,1) -> 47849 | H34: =DATE(YEAR(G34)+1,1,1) -> 48214 | I34: =DATE(YEAR(H34)+1,1,1) -> 48580 | J34: =DATE(YEAR(I34)+1,1,1) -> 48945 | K34: =DATE(YEAR(J34)+1,1,1) -> 49310 | L34: =DATE(YEAR(K34)+1,1,1) -> 49675
A35: 项目全投资现金流 | B35: =B13+B20 -> -358.4 | C35: =C13+C20 -> 61.170707 | D35: =D13+D20 -> 60.70519 | E35: =E13+E20 -> 60.248542 | F35: =F13+F20 -> 58.350933 | G35: =G13+G20 -> 52.035014 | H35: =H13+H20 -> 49.244293 | I35: =I13+I20 -> 47.700412 | ... L35: =L13+L20 -> 0
A36: 项目累积全投资现金流 | B36: =SUM($B35:B35) -> -358.4 | C36: =SUM($B35:C35) -> -297.22929 | D36: =SUM($B35:D35) -> -236.5241 | E36: =SUM($B35:E35) -> -176.27556 | F36: =SUM($B35:F35) -> -117.92463 | G36: =SUM($B35:G35) -> -65.889615 | H36: =SUM($B35:H35) -> -16.645322 | I36: =SUM($B35:I35) -> 31.05509 | ... L36: =SUM($B35:L35) -> 78.423206
A38: 五、财务评价指标
A39: 1.静态投资回收期（年） | C39: {=IFERROR(MATCH(0,$C$36:$L$36,1)-INDEX($C$36:$L$36,,MATCH(0,$C$36:$L$36,1))/INDEX($C$35:$L$35,,MATCH(0,$C$36:$L$36,1)+1)+YEARFRAC($B$34,$C$34,2),"无法回收")} -> 6.6906222
A40: =" 2.运营期NPV（折现率"&TEXT(B40,"#.0%")&"，万元）" -> 2.运营期NPV（折现率8.0%，万元） | B40: =输入!B56 -> 0.08 | C40: =XNPV($B$40,B35:L35,B34:L34) -> -22.472488
A41: 3.IRR（内部收益率） | C41: =XIRR(B35:L35,B34:L34,$B$40) -> 0.058809276
A42: 4.PI（盈利指数） | C42: =IF(B35<0,NPV($B$40,C35:L35)/(-B35),"N/A") -> 0.890826

Sheet Opex清单
A1: 系统 | B1: 分项 | C1: 明细 | D1: 运营费（含税） | E1: 单位 | F1: 税率 | G1: 不含税 | H1: VAT | J1: 假设依据
A2: 充电桩运维 | B2: 充电桩巡检费 | C2: 工单巡检 | D2: =N2 -> 0.7 | E2: 万元 | F2: 0.06 | G2: =D2/(1+F2) -> 0.66037736 | H2: =D2-G2 -> 0.039622642 | J2: 每季度巡检1次，直流桩50元/设备，超充算6个设备，快充算2各设备，上海上门费500元/次 | L2: =Capex清单!J2*6+Capex清单!J4*2+Capex清单!J5*2 -> 10 | M2: 50 | N2: 0.7
B3: 充电桩每年运维费 | C3: 易损件、零部件等 | D3: =N3 -> 3 | E3: 万元 | F3: 0.06 | G3: =D3/(1+F3) -> 2.8301887 | H3: =D3-G3 -> 0.16981132 | J3: 超充总价的6%/年，直流桩总价的5%/年，交流总价的5%/年 | N3: 3
B4: 充电桩运营人工 | D4: 2 | E4: 万元
B5: 充电桩保险费 | C5: 保险费 | D5: =N5 -> 0.255 | E5: 万元 | F5: 0.06 | G5: =D5/(1+F5) -> 0.24056604 | H5: =D5-G5 -> 0.014433962 | J5: 超充算4个设备，1个设备150/年，直流按桩数量算 | L5: 17 | M5: 0.015 | N5: =L5*M5 -> 0.255
B6: 智慧充电运营运维管理系统费* | C6: 订阅+运营费 | D6: 1 | E6: 万元 | F6: 0.06 | G6: =D6/(1+F6) -> 0.94339623 | H6: =D6-G6 -> 0.056603774 | J6: 超充3000，直流桩400（这里参考中德报价1w） | L6: 400 | M6: 100 | N6: =(3000*Capex清单!J2+400*Opex清单!J4+400*Capex清单!J5)/10000 -> 0.34
A7: 光伏 | B7: 光伏运维费 | C7: 巡检+维修 | D7: 0 | E7: 万元 | F7: 0.06 | G7: =D7/(1+F7) -> 0 | H7: =D7-G7 -> 0 | L7: 0 | N7: =L7*M7 -> 0
A8: 储能 | B8: 储能运维 | C8: 巡检+维修 | D8: =N8 -> 1.048 | E8: 万元 | F8: 0.06 | G8: =D8/(1+F8) -> 0.98867925 | H8: =D8-G8 -> 0.059320755 | J8: 20元/kwh | L8: =262*2 -> 524 | M8: 0.002 | N8: =L8*M8 -> 1.048
B9: 储能保险 | C9: 保险费 | D9: 0.000732 | E9: 万元 | F9: 0.06 | G9: =D9/(1+F9) -> 0.00069056604 | H9: =D9-G9 -> 4.1433962e-05 | J9: 设备总价的0.2% | L9: 0.002 | N9: =Capex清单!D8*L9 -> 0.03668
A10: 能源管理系统 | B10: 储充微网系统* | C10: 订阅费+运营费 | D10: 2 | E10: 万元 | F10: 0.06 | G10: =D10/(1+F10) -> 1.8867925 | H10: =D10-G10 -> 0.11320755 | J10: 按中德报价，微网系统2w | L10: 1 | M10: 0.6486 | N10: =L10*M10 -> 0.6486
A11: 车位租金 | B11: 车位费 | C11: 12个车位 | D11: 0 | E11: 万元 | F11: 0.06 | G11: =D11/(1+F11) -> 0 | H11: =D11-G11 -> 0 | J11: 按照分成的逻辑，与收入挂钩,这里不考虑分成
A12: 流量曝光 | B12: 地图投放、检索 | C12: 百度 | D12: 0 | E12: 万元 | F12: 0.06 | G12: =D12/(1+F12) -> 0 | H12: =D12-G12 -> 0 | J12: - | N12: 1
A13: 电损 | B13: 充电损耗 | C13: 5%耗电量 | D13: =N13 -> 5.6994737 | E13: 万元 | G13: =D13/(1+F13) -> 5.6994737 | H13: =D13-G13 -> 0 | J13: 用电损耗占总用电量5%，同时使用项目所在地平均电价 | N13: =(假设测算!C7*假设测算!C8*L5)/0.95*0.05*J17*350/10000 -> 5.6994737
A14: 运维费用合计 | D14: =SUM(D2:D13) -> 15.703206 | E14: 万元 | H14: =SUM(H2:H13) -> 0.45304143
J16: 充电桩成本电价
J17: 0.91

Sheet Capex清单
A1: 系统 | B1: 分项 | C1: 明细 | D1: 初投资（含税） | E1: 单位 | H1: 假设依据，设备价最下方 | J1: 数量 | K1: 单价 | L1: 总价
A2: 充电桩系统 | B2: 超充桩* | C2: 480kW一拖四 | D2: =K2 -> 50 | E2: 万元 | H2: 按照50w | J2: 1 | K2: 50 | L2: =K2*J2 -> 50
B3: 超充桩* | C3: 240kW一拖四 | D3: =L3 -> 0 | E3: 万元 | J3: 0 | L3: =J3*K3 -> 0
B4: 直流桩* | C4: 120kW一拖二 | D4: =L4 -> 13.6 | E4: 万元 | J4: 1 | K4: 3.4 | L4: =K4*4 -> 13.6
B5: V2G桩* | C5: 132kW一拖二 | D5: =L5 -> 9.8 | E5: 万元 | H5: 按照中德目前报价9.8w | J5: 1 | K5: 9.8 | L5: =J5*K5 -> 9.8
B6: 施工安装 | C6: 电缆、土建、安装等 | D6: =L6+15 -> 44.28 | E6: 万元 | H6: 典型场景造价 0.4元/瓦 | J6: =J2*480+J3*240+J4*120+J5*132 -> 732 | K6: 0.4 | L6: =J6*K6/10 -> 29.28
A7: 光伏 | B7: 588kW光伏系统 | C7: 包括安装、土建 | D7: =1680332/10000 -> 168.0332 | E7: 万元 | H7: (组件0.9/Wp) | J7: 0 | K7: 3.25 | L7: =J7*K7/10 -> 0
A8: 储能系统 | B8: 储能柜* | C8: 262kWh工商储柜*2 | D8: =L8 -> 18.34 | E8: 万元 | H8: 工商储0.7元/kwh | J8: 262 | K8: 0.7 | L8: =J8*K8/10 -> 18.34
B9: 施工安装 | C9: 安装+土建 | D9: =L9 -> 6.55 | E9: 万元 | H9: 0.25元/Wh | J9: 262 | K9: 0.25 | L9: =J9*K9/10 -> 6.55
A10: 智慧充电运营 | B10: 微网控制器EGC* | C10: 设备及授权 | D10: 12.9 | E10: 万元 | H10: 参考中德项目报价 | J10: 1 | K10: 0.8695 | L10: =J10*K10 -> 0.8695
A11: 运维管理系统 | B11: 接入费用* | C11: 充电桩接入费用 | D11: 0.5 | E11: 万元 | J11: 1 | K11: 1.5 | L11: =J11*K11 -> 1.5
A12: 其他 | B12: 场站协调 | C12: 道闸、监控系统API打通 | D12: =L12 -> 2 | E12: 万元 | H12: 项目规模差异不大，投入基本一致 | J12: 1 | K12: 2 | L12: =J12*K12 -> 2
B13: 设计及手续 | C13: 设计及相关手续 | D13: =L13 -> 10 | E13: 万元 | H13: 项目规模差异不大，投入基本一致 | J13: 1 | K13: 10 | L13: =J13*K13 -> 10
B14: 2000kVA箱变（购买设备） | D14: 30 | E14: 万元
A15: 合计 | D15: =SUM(D2:D13) -> 336.0032 | E15: 万元
