Workbook

Sheet 汇总表
A1: xx远景项目成本汇总表
A3: 序号 | B3: 项目 | C3: 容量（Wp） | D3: 造价（元） | E3: 其中甲供（元） | F3: 备注
A5: 1 | B5: 光伏工程设备费 | C5: =光伏工程!M3 -> 26040 | D5: =光伏工程!J213 -> 176932
A6: 2 | B6: 储能工程设备费 | D6: =储能工程!J129 -> 186400 | E6: =储能工程!J5 -> 183400
A7: 3 | B7: 充电桩工程设备费 | D7: =充电桩工程!J71 -> 618300 | E7: =充电桩工程!J7+充电桩工程!J9 -> 598000
A8: 4 | B8: 建安费 | D8: =光伏工程!K213+光伏工程!L213+储能工程!K129+储能工程!L129+充电桩工程!K71+充电桩工程!L71 -> 668923.36 | F8: 考虑冬季施工，建安费用上调10%
A9: 5 | B9: 额外要求成本 | D9: =光伏工程!L224+储能工程!L137+充电桩工程!L73 -> 0
A10: 6 | B10: 勘察设计费 | D10: =SUM(光伏工程!L215:L217) -> 30000 | F10: 含荷载报告
A11: 7 | B11: 手续费 | D11: =SUM(光伏工程!L219:L222) -> 50000 | F11: 含接入手续办理及并网验收费用
A12: 8 | B12: 安措费 | D12: =D8*3% -> 20067.701 | F12: 安措费=（序号4）*3%
A13: 9 | B13: 财务费用 | D13: 0 | F13: 根据业务模式计算
A14: 10 | B14: EPC管理费及利润 | D14: =(SUM(D5:D8)-SUM(E5:E8))*6% -> 52149.322 | F14: 管理及利润=（序号1234）*6%，不含甲供材料
A15: 11 | B15: 工程保险费 | D15: =SUM(D5:D14)*0.0005+1000000*0.0015+900*10*C5/1000000 -> 2635.7462 | F15: 工程一切险，第三者责任险，承包商雇员险
A16: 12 | B16: 不可预见费 | D16: =SUM(D5:D15)*1.5% -> 27081.122 | F16: 不可预见费=（序号123456789）*1.5%，含甲供材料
B17: 合计 | D17: =SUM(D5:D16) -> 1832489.3 | E17: =SUM(E5:E16) -> 781400
B18: 每Wp造价 | D18: =D17/C5 -> 70.372091 | E18: =E17/C5 -> 30.00768

Sheet 光伏工程
A1: 光伏工程
A2: 分类 | B2: 序号 | C2: 项目名称 | D2: 特征描述 | E2: 单位 | F2: 工程量 | G2: 综合单价 | J2: 合价 | M2: 容量 | N2: 综合单价系数
G3: 设备费 | H3: 主材费 | I3: 建安费 | J3: 设备费 | K3: 主材费 | L3: 建安费 | M3: =F6*620 -> 26040 | N3: =1.1*1 -> 1.1
A4: 光伏设备及建安成本 | B4: 1 | C4: 光伏阵列
B5: 1.1 | C5: 光伏组件及安装
D6: 组件功率：620Wp（TOPCon一线） | E6: 块 | F6: 42 | G6: =0.8*620 -> 496 | I6: =22*$N$3 -> 24.2 | J6: =F6*G6 -> 20832 | L6: =F6*I6 -> 1016.4
D7: 组件功率：Wp（BC一线） | E7: 块 | G7: =(0.67+0.05)*600 -> 432 | I7: =22*$N$3 -> 24.2 | J7: =F7*G7 -> 0 | L7: =F7*I7 -> 0
B8: 1.2 | C8: 组件排泥器 | E8: 个 | F8: 84 | I8: =1.8*$N$3 -> 1.98 | L8: =F8*I8 -> 166.32
B9: 1.3 | C9: MC4接头 | D9: 组件串*4 | E9: 套 | F9: 10 | I9: =2.7*$N$3 -> 2.97 | L9: =F9*I9 -> 29.7
B10: 2 | C10: 变配电装置
B11: 2.1 | C11: 逆变器
C12: 组串逆变器 | D12: 华为50KW | E12: 台 | G12: 8400 | I12: =1000*$N$3 -> 1100 | J12: =F12*G12 -> 0 | L12: =F12*I12 -> 0
C13: 组串逆变器 | D13: 华为100KW | E13: 台 | G13: 18600 | I13: =1000*$N$3 -> 1100 | J13: =F13*G13 -> 0 | L13: =F13*I13 -> 0
C14: 组串逆变器 | D14: 华为110KW | E14: 台 | G14: 18600 | I14: =1000*$N$3 -> 1100 | J14: =F14*G14 -> 0 | L14: =F14*I14 -> 0
C15: 组串逆变器 | D15: 华为150KW | E15: 台 | G15: 22100 | I15: =1000*$N$3 -> 1100 | J15: =F15*G15 -> 0 | L15: =F15*I15 -> 0
C16: 组串逆变器 | D16: 华为300KW | E16: 台 | G16: 32900 | I16: =1000*$N$3 -> 1100 | J16: =F16*G16 -> 0 | L16: =F16*I16 -> 0
C17: 组串逆变器 | D17: 阳光30kW | E17: 台 | F17: 1 | G17: 4800 | I17: =1000*$N$3 -> 1100 | J17: =F17*G17 -> 4800 | L17: =F17*I17 -> 1100
C18: 组串逆变器 | D18: 阳光110kW | E18: 台 | G18: 16520 | I18: =1000*$N$3 -> 1100 | J18: =F18*G18 -> 0 | L18: =F18*I18 -> 0
C19: 组串逆变器 | D19: 阳光150kW | E19: 台 | G19: 20250 | I19: =1000*$N$3 -> 1100 | J19: =F19*G19 -> 0 | L19: =F19*I19 -> 0
C20: 组串逆变器 | D20: 阳光250kW | E20: 台 | G20: 21100 | I20: =1000*$N$3 -> 1100 | J20: =F20*G20 -> 0 | L20: =F20*I20 -> 0
C21: 组串逆变器 | D21: 阳光320kW | E21: 台 | G21: 33400 | I21: =1000*$N$3 -> 1100 | J21: =F21*G21 -> 0 | L21: =F21*I21 -> 0
C22: 组串逆变器 | D22: 锦浪50KW | E22: 台 | G22: 6400 | I22: =1000*$N$3 -> 1100 | J22: =F22*G22 -> 0 | L22: =F22*I22 -> 0
C23: 组串逆变器 | D23: 锦浪100KW | E23: 台 | G23: 14600 | I23: =1000*$N$3 -> 1100 | J23: =F23*G23 -> 0 | L23: =F23*I23 -> 0
C24: 组串逆变器 | D24: 锦浪150KW | E24: 台 | G24: 20000 | I24: =1000*$N$3 -> 1100 | J24: =F24*G24 -> 0 | L24: =F24*I24 -> 0
C25: 组串逆变器 | D25: 锦浪320kW | E25: 台 | G25: 32560 | I25: =1000*$N$3 -> 1100 | J25: =F25*G25 -> 0 | L25: =F25*I25 -> 0
B26: 2.2 | C26: 箱变
C27: 欧式箱变 | D27: SCB12-800/10.5/0.5kV （铜绕组，高压侧为负荷开关+熔断器） | E27: 台 | F27: 1 | G27: 149000 | I27: =3000*$N$3 -> 3300 | J27: =F27*G27 -> 149000 | L27: =F27*I27 -> 3300 | M27: 备注：升级为2级能耗，在此价格基础上加4万，高压侧升级为断路器方案，在此价格上加3万，高压侧升级环网柜方案，在此基础上加6万。
C28: 新增箱变对端侧改造 | F28: 1 | I28: 50000 | J28: =F28*G28 -> 0 | L28: =F28*I28 -> 50000
C29: 欧式箱变 | D29: SCB12-1000/10.5/0.9kV（铜绕组，高压侧为负荷开关+熔断器） | E29: 台 | G29: 185000 | I29: =3000*$N$3 -> 3300 | J29: =F29*G29 -> 0 | L29: =F29*I29 -> 0
C30: 欧式箱变 | D30: SCB12-1250/10.5/0.10kV（铜绕组，高压侧为负荷开关+熔断器） | E30: 台 | G30: 210000 | I30: =3000*$N$3 -> 3300 | J30: =F30*G30 -> 0 | L30: =F30*I30 -> 0
C31: 欧式箱变 | D31: SCB12-1600/10.5/0.11kV（铜绕组，高压侧为负荷开关+熔断器） | E31: 台 | G31: 255000 | I31: =3000*$N$3 -> 3300 | J31: =F31*G31 -> 0 | L31: =F31*I31 -> 0
C32: 欧式箱变 | D32: SCB12-2000/10.5/0.12kV（铜绕组，高压侧为负荷开关+熔断器） | E32: 台 | G32: 275000 | I32: =3000*$N$3 -> 3300 | J32: =F32*G32 -> 0 | L32: =F32*I32 -> 0
C33: 欧式箱变 | D33: SCB12-2500/10.5/0.13kV（铜绕组，高压侧为负荷开关+熔断器） | E33: 台 | G33: 305000 | I33: =3000*$N$3 -> 3300 | J33: =F33*G33 -> 0 | L33: =F33*I33 -> 0
C34: 欧式箱变 | D34: SCB12-3150/10.5/0.14kV（铜绕组，高压侧为负荷开关+熔断器） | E34: 台 | G34: 325000 | I34: =3000*$N$3 -> 3300 | J34: =F34*G34 -> 0 | L34: =F34*I34 -> 0
B35: 2.3 | C35: 开关柜
D36: 10kV 并网柜（KYN28A-12，Ir=630A,Ib=25kA) | E36: 面 | G36: 52000 | I36: =1000*$N$3 -> 1100 | J36: =F36*G36 -> 0 | L36: =F36*I36 -> 0
D37: 10kV 出线柜（KYN28A-12，Ir=630A,Ib=25kA） | E37: 面 | G37: 52000 | I37: =1000*$N$3 -> 1100 | J37: =F37*G37 -> 0 | L37: =F37*I37 -> 0
D38: 10KV PT柜（KYN28A-12，Ib=25kA） | E38: 面 | G38: 30340 | I38: =1000*$N$3 -> 1100 | J38: =F38*G38 -> 0 | L38: =F38*I38 -> 0
D39: 10KV 计量柜（KYN28A-12，Ir=630A,Ib=25kA） | E39: 面 | G39: 25000 | I39: =1000*$N$3 -> 1100 | J39: =F39*G39 -> 0 | L39: =F39*I39 -> 0
D40: 10KV SVG柜（KYN28A-12，Ir=630A,Ib=25kA） | E40: 面 | G40: 50800 | I40: =1000*$N$3 -> 1100 | J40: =F40*G40 -> 0 | L40: =F40*I40 -> 0
...

Sheet 储能工程
A1: 储能工程
A2: 分类 | B2: 序号 | C2: 项目名称 | D2: 特征描述 | E2: 单位 | F2: 工程量 | G2: 综合单价 | J2: 合价 | M2: 综合单价系数
G3: 设备费 | H3: 主材费 | I3: 建安费 | J3: 设备费 | K3: 主材费 | L3: 建安费 | M3: =1.1*1 -> 1.1
A4: 储能设备及建安成本 | B4: 1 | C4: 储能柜
B5: 1.1 | C5: 储能柜及安装 | D5: 125KW/262kWh | E5: 台 | F5: 1 | G5: =262000*0.7 -> 183400 | I5: =2000*$M$3 -> 2200 | J5: =F5*G5 -> 183400 | L5: =F5*I5 -> 2200
B6: 2 | C6: 变配电装置
B7: 2.1 | C7: 箱变
C8: 欧式箱变 | D8: SCB12-800/10.5/0.8kV （铜绕组，高压侧为负荷开关+熔断器） | E8: 台 | G8: 169000 | I8: =3000*$M$3 -> 3300 | J8: =F8*G8 -> 0 | L8: =F8*I8 -> 0
D9: SCB12-1000/10.5/0.9kV（铜绕组，高压侧为负荷开关+熔断器） | E9: 台 | G9: 185000 | I9: =3000*$M$3 -> 3300 | J9: =F9*G9 -> 0 | L9: =F9*I9 -> 0
D10: SCB12-1250/10.5/0.10kV（铜绕组，高压侧为负荷开关+熔断器） | E10: 台 | G10: 210000 | I10: =3000*$M$3 -> 3300 | J10: =F10*G10 -> 0 | L10: =F10*I10 -> 0
D11: SCB12-1600/10.5/0.11kV（铜绕组，高压侧为负荷开关+熔断器） | E11: 台 | G11: 255000 | I11: =3000*$M$3 -> 3300 | J11: =F11*G11 -> 0 | L11: =F11*I11 -> 0
D12: SCB12-2000/10.5/0.12kV（铜绕组，高压侧为负荷开关+熔断器） | E12: 台 | G12: 275000 | I12: =3000*$M$3 -> 3300 | J12: =F12*G12 -> 0 | L12: =F12*I12 -> 0
D13: SCB12-2500/10.5/0.13kV（铜绕组，高压侧为负荷开关+熔断器） | E13: 台 | G13: 305000 | I13: =3000*$M$3 -> 3300 | J13: =F13*G13 -> 0 | L13: =F13*I13 -> 0
D14: SCB12-3150/10.5/0.14kV（铜绕组，高压侧为负荷开关+熔断器） | E14: 台 | G14: 325000 | I14: =3000*$M$3 -> 3300 | J14: =F14*G14 -> 0 | L14: =F14*I14 -> 0
B15: 2.2 | C15: 开关柜
D16: 10kV 并网柜（KYN28A-12，Ir=630A,Ib=25kA) | E16: 面 | G16: 52000 | I16: =1000*$M$3 -> 1100 | J16: =F16*G16 -> 0 | L16: =F16*I16 -> 0
D17: 10kV 出线柜（KYN28A-12，Ir=630A,Ib=25kA） | E17: 面 | G17: 52000 | I17: =1000*$M$3 -> 1100 | J17: =F17*G17 -> 0 | L17: =F17*I17 -> 0
D18: 10KV PT柜（KYN28A-12，Ib=25kA） | E18: 面 | G18: 30340 | I18: =1000*$M$3 -> 1100 | J18: =F18*G18 -> 0 | L18: =F18*I18 -> 0
D19: 10KV 计量柜（KYN28A-12，Ir=630A,Ib=25kA） | E19: 面 | G19: 25000 | I19: =1000*$M$3 -> 1100 | J19: =F19*G19 -> 0 | L19: =F19*I19 -> 0
D20: 10KV SVG柜（KYN28A-12，Ir=630A,Ib=25kA） | E20: 面 | G20: 50800 | I20: =1000*$M$3 -> 1100 | J20: =F20*G20 -> 0 | L20: =F20*I20 -> 0
D21: 10KV 光伏集电线柜（KYN28A-12，Ir=630A,Ib=25kA） | E21: 面 | G21: 52000 | I21: =1000*$M$3 -> 1100 | J21: =F21*G21 -> 0 | L21: =F21*I21 -> 0
D22: 10kv 站用变柜（KYN28A-12，Ir=630A,Ib=25kA） | E22: 面 | G22: 40000 | I22: =1000*$M$3 -> 1100 | J22: =F22*G22 -> 0 | L22: =F22*I22 -> 0
D23: 400V 并网柜（GGD柜，国内一线框架断路器630A） | E23: 面 | G23: 20000 | I23: =1000*$M$3 -> 1100 | J23: =F23*G23 -> 0 | L23: =F23*I23 -> 0
D24: 400V 并网柜（GGD柜，国内一线框架断路器1250A） | E24: 面 | G24: 25000 | I24: =1000*$M$3 -> 1100 | J24: =F24*G24 -> 0 | L24: =F24*I24 -> 0
D25: 400V 并网柜（GGD柜，ABB框架断路器1250A） | E25: 面 | G25: 35000 | I25: =1000*$M$3 -> 1100 | J25: =F25*G25 -> 0 | L25: =F25*I25 -> 0
B26: 2.3 | C26: SVG设备
C27: 10kV 直挂SVG | D27: ±0.5Mvar | E27: 台 | G27: 180000 | I27: =2000*$M$3 -> 2200 | J27: =F27*G27 -> 0 | L27: =F27*I27 -> 0
D28: ±1Mvar | E28: 台 | G28: 208000 | I28: =2000*$M$3 -> 2200 | J28: =F28*G28 -> 0 | L28: =F28*I28 -> 0
D29: ±1.5Mvar | E29: 台 | G29: 213000 | I29: =2000*$M$3 -> 2200 | J29: =F29*G29 -> 0 | L29: =F29*I29 -> 0
D30: ±2Mvar | E30: 台 | G30: 220000 | I30: =2000*$M$3 -> 2200 | J30: =F30*G30 -> 0 | L30: =F30*I30 -> 0
C31: 400V 电容柜 | D31: GGD柜 ,600kvar | E31: 台 | G31: 30000 | I31: =1000*$M$3 -> 1100 | J31: =F31*G31 -> 0 | L31: =F31*I31 -> 0
B32: 2.4 | C32: 站用电
C33: 10kv站用变 | D33: 50KVA | E33: 台 | G33: 20000 | I33: =2000*$M$3 -> 2200 | J33: =F33*G33 -> 0 | L33: =F33*I33 -> 0
C34: 低压站用柜 | D34: GGD柜 ,双电源供电 | E34: 面 | G34: 20000 | I34: =1000*$M$3 -> 1100 | J34: =F34*G34 -> 0 | L34: =F34*I34 -> 0
B35: 2.5 | C35: 预制舱
C36: 一次预制舱 | D36: 6.5*3.5*3 | E36: 台 | G36: =6.5*3.5*3000 -> 68250 | I36: =5000*$M$3 -> 5500 | J36: =F36*G36 -> 0 | L36: =F36*I36 -> 0
C37: 二次预制舱 | D37: 6*3.5*3 | E37: 台 | G37: =6*3.5*3000 -> 63000 | I37: =5000*$M$3 -> 5500 | J37: =F37*G37 -> 0 | L37: =F37*I37 -> 0
C38: 一二次预制舱 | D38: 9.5*3.5*3 | E38: 台 | G38: =9.5*3.5*3000 -> 99750 | I38: =10000*$M$3 -> 11000 | J38: =F38*G38 -> 0 | L38: =F38*I38 -> 0
B39: 3 | C39: 电气二次
B40: 3.1 | C40: 10kV并网
...

Sheet 充电桩工程
A1: 充电桩工程
A2: 分类 | B2: 序号 | C2: 项目名称 | D2: 特征描述 | E2: 单位 | F2: 工程量 | G2: 综合单价 | J2: 合价 | M2: 综合单价系数
G3: 设备费 | H3: 主材费 | I3: 建安费 | J3: 设备费 | K3: 主材费 | L3: 建安费 | M3: =1.05*1 -> 1.05
A4: 充电桩设备及建安成本 | B4: 1 | C4: 充电桩
B5: 1.1 | C5: 充电桩安装 | D5: 7kW交流充电桩 | E5: 台 | I5: =200*$M$3 -> 210 | J5: =F5*G5 -> 0 | L5: =F5*I5 -> 0
B6: 1.2 | C6: 充电桩安装 | D6: 60kW直流充电桩 | E6: 台 | I6: =500*$M$3 -> 525 | J6: =F6*G6 -> 0 | L6: =F6*I6 -> 0
B7: 1.3 | C7: 充电桩安装 | D7: 132kW直流充电桩 V2G | E7: 台 | F7: 1 | G7: 98000 | I7: =1000*$M$3 -> 1050 | J7: =F7*G7 -> 98000 | L7: =F7*I7 -> 1050
B8: 1.4 | C8: 充电桩安装 | D8: 240kW直流充电桩 | E8: 台 | I8: =2000*$M$3 -> 2100 | J8: =F8*G8 -> 0 | L8: =F8*I8 -> 0
B9: 1.5 | C9: 充电桩安装 | D9: 480kW直流充电桩（含终端1拖4） | E9: 台 | F9: 1 | G9: 500000 | I9: =7500*$M$3 -> 7875 | J9: =F9*G9 -> 500000 | L9: =F9*I9 -> 7875
B10: 2 | C10: 变配电装置
B11: 2.1 | C11: 开关柜
D12: 400V 并网柜（GGD柜，国内一线框架断路器630A） | E12: 面 | G12: 20000 | I12: =1000*$M$3 -> 1050 | J12: =F12*G12 -> 0 | L12: =F12*I12 -> 0
D13: 400V 并网柜（GGD柜，国内一线框架断路器1250A） | E13: 面 | G13: 25000 | I13: =1000*$M$3 -> 1050 | J13: =F13*G13 -> 0 | L13: =F13*I13 -> 0
D14: 400V 并网柜（GGD柜，250A*2塑断+500A塑断*2+50A塑断+25A*3塑断） | E14: 面 | F14: 1 | G14: 18000 | I14: =1000*$M$3 -> 1050 | J14: =F14*G14 -> 18000 | L14: =F14*I14 -> 1050
B15: 3 | C15: 租用平台管理系统
B16: 3.1 | C16: 充电云平台 | E16: 套 | G16: 2000 | I16: =500*$M$3 -> 525 | J16: =F16*G16 -> 0 | L16: =F16*I16 -> 0
B17: 3.2 | C17: 对接服务 | E17: 套 | G17: 20000 | I17: =500*$M$3 -> 525 | J17: =F17*G17 -> 0 | L17: =F17*I17 -> 0
B18: 3.3 | C18: 关口计量表 | D18: 0.2S级计量表 | E18: 套 | F18: 1 | G18: 2300 | I18: =100*$M$3 -> 105 | J18: =F18*G18 -> 2300 | L18: =F18*I18 -> 105
B19: 4 | C19: 电缆
B20: 4.1 | C20: 通信线缆
C21: 通信线缆 | D21: ZRC-kvvp2-22-0.45/0.75kV-2×4mm² | E21: m | H21: =11*$M$3 -> 11.55 | I21: =5*$M$3 -> 5.25 | K21: =F21*H21 -> 0 | L21: =F21*I21 -> 0
C22: RS485屏蔽双绞线 | D22: RVVP2*1.5mm² | E22: m | F22: 50 | H22: =5*$M$3 -> 5.25 | I22: =5*$M$3 -> 5.25 | K22: =F22*H22 -> 262.5 | L22: =F22*I22 -> 262.5
B23: 4.2 | C23: 低压交流电力电缆
D24: ZC-YJLHV22-0.6/1kV-3×150mm²+1×70mm² | E24: m | H24: =55.9*$M$3 -> 58.695 | I24: =20*$M$3 -> 21 | K24: =F24*H24 -> 0 | L24: =F24*I24 -> 0
D25: ZC-YJLHV22-0.6/1kV-3×240mm²+1×120mm² | E25: m | H25: =86.92*$M$3 -> 91.266 | I25: =20*$M$3 -> 21 | K25: =F25*H25 -> 0 | L25: =F25*I25 -> 0
D26: ZC-YJLHV22-0.6/1kV-3×300mm²+1×150mm² | E26: m | F26: 400 | H26: =111.65*$M$3 -> 117.2325 | I26: =20*$M$3 -> 21 | K26: =F26*H26 -> 46893 | L26: =F26*I26 -> 8400
D27: ZC-YJLHV22-0.6/1kV-3×240mm²+2×120mm² | E27: m | F27: 20 | H27: =102.32*$M$3 -> 107.436 | I27: =20*$M$3 -> 21 | K27: =F27*H27 -> 2148.72 | L27: =F27*I27 -> 420
D28: ZC-YJV22-0.6/1kV-4×240mm² | E28: m | F28: 80 | H28: =981.63*$M$3 -> 1030.7115 | I28: =20*$M$3 -> 21 | K28: =F28*H28 -> 82456.92 | L28: =F28*I28 -> 1680
D29: ZC-YJV22-0.6/1kV-1×70mm² | E29: m | F29: 80 | H29: =69.93*$M$3 -> 73.4265 | I29: =20*$M$3 -> 21 | K29: =F29*H29 -> 5874.12 | L29: =F29*I29 -> 1680
D30: ZC-YJV22-0.6/1kV-3×185mm²+2×95mm² | E30: m | F30: 20 | H30: =755.09*$M$3 -> 792.8445 | I30: =20*$M$3 -> 21 | K30: =F30*H30 -> 15856.89 | L30: =F30*I30 -> 420
B31: 4.3 | C31: 低压电缆头 | E31: 套 | F31: 32 | H31: =200*$M$3 -> 210 | I31: =200*$M$3 -> 210 | K31: =F31*H31 -> 6720 | L31: =F31*I31 -> 6720
B32: 4.4 | C32: 电缆保护管
C33: 软管 | D33: Φ50*3.7 PE材质 | E33: m | H33: =3*$M$3 -> 3.15 | I33: =8*$M$3 -> 8.4 | K33: =F33*H33 -> 0 | L33: =F33*I33 -> 0
C34: 不锈钢管 | D34: SC100，4.5mm厚 | E34: m | H34: =190*$M$3 -> 199.5 | I34: =15*$M$3 -> 15.75 | K34: =F34*H34 -> 0 | L34: =F34*I34 -> 0
C35: 不锈钢管 | D35: SC150，4.5mm厚 | E35: m | H35: =280*$M$3 -> 294 | I35: =15*$M$3 -> 15.75 | K35: =F35*H35 -> 0 | L35: =F35*I35 -> 0
C36: 热镀锌钢管 | D36: φ50 | E36: m | F36: 60 | H36: =32*$M$3 -> 33.6 | I36: =17*$M$3 -> 17.85 | K36: =F36*H36 -> 2016 | L36: =F36*I36 -> 1071
C37: 热镀锌钢管 | D37: φ100 | E37: m | F37: =40 -> 40 | H37: =60*$M$3 -> 63 | I37: =28*$M$3 -> 29.4 | K37: =F37*H37 -> 2520 | L37: =F37*I37 -> 1176
C38: 热镀锌钢管 | D38: φ125 | E38: m | H38: =85*$M$3 -> 89.25 | I38: =32*$M$3 -> 33.6 | K38: =F38*H38 -> 0 | L38: =F38*I38 -> 0
C39: 热镀锌钢管 | D39: φ150 | E39: m | H39: =110*$M$3 -> 115.5 | I39: =37*$M$3 -> 38.85 | K39: =F39*H39 -> 0 | L39: =F39*I39 -> 0
B40: 5 | C40: 接地及辅材
...

Sheet 调整系数
B1: 建安费（含主材）调整系数
B2: 光伏项目容量 | C2: ≤1MW | D2: 1MW＜x≤3MW | E2: 3MW＜x≤6MW | F2: ＞6MW
B3: 调整系数 | C3: 1.1 | D3: 1.05 | E3: 1 | F3: 0.95
B5: 储能项目容量 | C5: ≤2MWh | D5: 2MWh＜x≤6MWh | E5: 6MWh＜x≤12MWh | F5: ＞12MWh
B6: 调整系数 | C6: 1.1 | D6: 1.05 | E6: 1 | F6: 0.95
B8: 充电桩项目容量 | C8: ≤0.5MW | D8: 0.5MW＜x≤2.5MW | E8: 2.5MW＜x≤5MWh | F8: ＞5MWh
B9: 调整系数 | C9: 1.1 | D9: 1.05 | E9: 1 | F9: 0.95
B11: 地区 | C11: 一类地区 | D11: 二类地区 | E11: 三类地区 | F11: 四类地区
B12: 调整系数 | C12: 1.1 | D12: 1 | E12: 1.05 | F12: 1.1
B13: 一类地区 | C13: 北京，天津，上海，浙江，江苏，广东，深圳
B14: 二类地区 | C14: 河北，山西，陕西，山东，辽宁，安徽，四川，重庆，湖南，湖北，福建，江西，河南，广西
B15: 三类地区 | C15: 甘肃，宁夏，青海，黑龙江，吉林，贵州，海南，云南
B16: 四类地区 | C16: 内蒙古，新疆，西藏

Sheet 微网方案
A1: 沈阳某项目微网控制器策略方案
A2: 版本：V2.0 | B2: 安科瑞DTSD1352电表(CT160) 地址是204
A3: 适用范围：仅可控制储能PCS与光伏逆变器，充电桩及V2G桩均视为不可控负载
A5: 一、系统参数与安全红线（硬约束）
A6: 1.1 设备配置
A7: 设备 | B7: 关键参数 | C7: 可控性
A8: 变压器 | B8: 500kVA | C8: ——
A9: 储能系统 | B9: 容量262kWh，PCS额定功率 125kW（充放电） | C9: 完全可控
A10: 光伏 | B10: （光伏功率组件：42块620wp）26kW，逆变器：30KW，支持功率限发/关断指令 | C10: 完全可控
A11: 分体式充电桩 | B11: 总功率480kW，4终端动态分配 | C11: 不可控
A12: V2G充电桩 | B12: 额定120kW（一般车端最大放电功率 40kW，充电120KW）充放均不可控 | C12: 不可控
A14: 1.2 核心安全红线（优先级最高，任何时刻必须满足）
A15: 安全指标 | B15: 设定值 | C15: 说明
A16: 防逆流硬底线 | B16: 电网关口功率 Pgrid≥0Pgrid​≥0 kW，绝对不允许反向电流
A17: 控制响应时间 | B17: 从异常检测到功率指令下发 ≤100ms，3秒内完成闭环 | C17: 本地高速采样与直连通讯
A19: 二、控制架构与优先级
A20: 控制器实时采集 Ppv,Pload,SOC,PgridPpv​,Pload​,SOC,Pgrid​，每 100ms 执行一次策略循环。所有模式遵循以下优先级：
A21: 防逆流安全链 → 防超需安全链 → 分时经济调度
A22: 安全链一旦触发，直接越过经济调度，向储能和光伏下发强制指令。当电网功率恢复到安全区间后，无故障保持5秒，安全链退出，交回经济调度。
A25: 四、沈阳分时电价导入
A26: 根据辽宁省分时电价政策，配置如下时段表（示例价格，可通过参数更新）：
A27: 时段类型 | B27: 时间段 | C27: 执行月份
A28: 谷段 | B28: 22:00-次日5:00 | C28: 全年
A29: 平段 | B29: 5:00-7:30, 10:30-16:00, 21:00-22:00 | C29: 全年
A30: 高峰 | B30: 7:30-10:30, 16:00-18:00, 20:00-21:00 | C30: 全年
A31: 尖峰 | B31: 18:00-20:00 | C31: 7,8,12,1月执行，其余月份按高峰计价
A33: 特殊情况：
A34: 夏季/冬季尖峰（执行月份：1月、7月、8月、12月） | B34: 执行时间：18：00 - 20：00；逻辑：在这4个月份里，原本属于“高峰”的 18：00-20：00 升级为“尖峰”。
A35: 7月和8月的午间谷电（“深谷”） | B35: 辽宁省为了促进光伏消纳，在光伏大发的中午时段设置了更便宜的电价（通常称为深谷或低谷延伸）。 执行月份：7月、8月 具体时段：11：30 - 13：30 逻辑：这2个月份里，原本属于“平段”的 11：30-13：30 调整为“谷段”电价（或平时段电价下浮更大比例，具体看细则）。对于您的策略：如果此时光伏大发，优先用光伏；如果光伏不足，这2小时的电价比平时便宜，储能的充放电策略需要留意。
A36: 控制器需支持远程更新电价、时段及尖峰执行日期。
A38: 时间范围 | B38: 默认电价类型 | C38: 特殊规则触发条件
A39: 00：00 - 05：00 | B39: 谷段 | C39: 无
A40: 05：00 - 07：30 | B40: 平段 | C40: 无
A41: 07：30 - 10：30 | B41: 高峰 | C41: 无
A42: 10：30 - 11：30 | B42: 平段 | C42: 无
A43: 11：30 - 13：30 | B43: 平段 | C43: 若月份=7或8，调整为谷段电价
A44: 13：30 - 16：00 | B44: 平段 | C44: 无
A45: 16：00 - 18：00 | B45: 高峰 | C45: 无
A46: 18：00 - 20：00 | B46: 高峰 | C46: 若月份=1、7、8、12，调整为尖峰电价
A47: 20：00 - 21：00 | B47: 高峰 | C47: 无
...
